Workbook

Sheet merge
A1: 장소ID | B1: 관광지명 | C1: 장소명 | D1: 지역 | E1: 도로명주소 | F1: 실내구분 | G1: 카테고리 | H1: 카테고리코드 | I1: 카테고리명 | J1: 운영시간 (휴무일 포함) | K1: 전화번호 | L1: 홈페이지 | M1: 평점 | N1: 평점건수 | O1: 리뷰수 | P1: 최소 금액 (Min/1인) | Q1: 최대 금액 (Max/1인) | R1: 비고 (산출 근거) | S1: 상세URL | T1: 경도 | U1: 위도
A2: 581024580 | B2: 2018 평창 동계올림픽대회 및 동계패럴림픽대회 기념관 | C2: =VLOOKUP(A2,budget!$A$5:$I$337,3,FALSE) -> 2018평창동계올림픽대회 및 동계패럴림픽대회기념관 | D2: =VLOOKUP(B2,api!$A$2:$R$334,2,FALSE) -> 평창군 | E2: =VLOOKUP(B2,api!$A$2:$R$334,12,FALSE) -> 강원특별자치도 평창군 대관령면 횡계리 725 | F2: 실내 | G2: =VLOOKUP(A2,budget!$A$5:$I$337,4,FALSE) -> 국공립 박물관/기념관 | H2: CT1 | I2: 문화시설 | J2: =VLOOKUP(A2,budget!$A$5:$I$337,5,FALSE) -> 09:00 - 18:00 (월요일 휴무) | K2: =VLOOKUP(B2,api!$A$2:$R$334,14,FALSE) -> 033-330-5280 | L2: =VLOOKUP(B2,api!$A$2:$R$334,4,FALSE) -> https://pom2018.org/ | M2: =VLOOKUP(B2,api!$A$2:$R$334,5,FALSE) -> 4.7 | N2: =VLOOKUP(B2,api!$A$2:$R$334,6,FALSE) -> 27 | O2: =VLOOKUP(B2,api!$A$2:$R$334,7,FALSE) -> 173 | P2: =VLOOKUP(A2,budget!$A$5:$I$337,6,FALSE) -> 0 | Q2: =VLOOKUP(A2,budget!$A$5:$I$337,7,FALSE) -> 3000 | R2: =VLOOKUP(A2,budget!$A$5:$I$337,8,FALSE) -> 국공립 시설 무료 관람 또는 대인 기준 정가 | S2: =VLOOKUP(A2,budget!$A$5:$I$337,9,FALSE) -> http://place.map.kakao.com/581024580 | T2: =VLOOKUP(B2,api!$A$2:$R$334,17,FALSE) -> 128.70672 | U2: =VLOOKUP(B2,api!$A$2:$R$334,18,FALSE) -> 37.666839
A3: 25045748 | B3: 365세이프타운 | C3: =VLOOKUP(A3,budget!$A$5:$I$337,3,FALSE) -> 365세이프타운 | D3: =VLOOKUP(B3,api!$A$2:$R$334,2,FALSE) -> 태백시 | E3: =VLOOKUP(B3,api!$A$2:$R$334,12,FALSE) -> 강원특별자치도 태백시 장성동 31-2 | F3: 실내 | G3: =VLOOKUP(A3,budget!$A$5:$I$337,4,FALSE) -> 테마파크/민간관광지 | H3: AT4 | I3: 관광명소 | J3: =VLOOKUP(A3,budget!$A$5:$I$337,5,FALSE) -> 09:00 - 18:00 (월요일 휴무) | K3: =VLOOKUP(B3,api!$A$2:$R$334,14,FALSE) -> 033-550-3101 | L3: =VLOOKUP(B3,api!$A$2:$R$334,4,FALSE) -> http://www.taebaek.go.kr/365safetown/index.do | M3: =VLOOKUP(B3,api!$A$2:$R$334,5,FALSE) -> 4.5 | N3: =VLOOKUP(B3,api!$A$2:$R$334,6,FALSE) -> 37 | O3: =VLOOKUP(B3,api!$A$2:$R$334,7,FALSE) -> 163 | P3: =VLOOKUP(A3,budget!$A$5:$I$337,6,FALSE) -> 8000 | Q3: =VLOOKUP(A3,budget!$A$5:$I$337,7,FALSE) -> 20000 | R3: =VLOOKUP(A3,budget!$A$5:$I$337,8,FALSE) -> 대인 정상 입장료 기준 (할인혜택/통합권 따라 변동) | S3: =VLOOKUP(A3,budget!$A$5:$I$337,9,FALSE) -> http://place.map.kakao.com/25045748 | T3: =VLOOKUP(B3,api!$A$2:$R$334,17,FALSE) -> 129.02461 | U3: =VLOOKUP(B3,api!$A$2:$R$334,18,FALSE) -> 37.100491
A4: 1310990190 | B4: BTS버스정류장 | C4: =VLOOKUP(A4,budget!$A$5:$I$337,3,FALSE) -> BTS 버스정류장 | D4: =VLOOKUP(B4,api!$A$2:$R$334,2,FALSE) -> 강릉시 | E4: =VLOOKUP(B4,api!$A$2:$R$334,12,FALSE) -> 강원특별자치도 강릉시 주문진읍 향호리 8-39 | F4: 실외 | G4: =VLOOKUP(A4,budget!$A$5:$I$337,4,FALSE) -> 자연경관/자유관광지 | J4: =VLOOKUP(A4,budget!$A$5:$I$337,5,FALSE) -> 상시 개방 | K4: =VLOOKUP(B4,api!$A$2:$R$334,14,FALSE) -> 0 | L4: =VLOOKUP(B4,api!$A$2:$R$334,4,FALSE) -> https://www.gn.go.kr/tour/index.do | M4: =VLOOKUP(B4,api!$A$2:$R$334,5,FALSE) -> 4.3 | N4: =VLOOKUP(B4,api!$A$2:$R$334,6,FALSE) -> 63 | O4: =VLOOKUP(B4,api!$A$2:$R$334,7,FALSE) -> 113 | P4: =VLOOKUP(A4,budget!$A$5:$I$337,6,FALSE) -> 0 | Q4: =VLOOKUP(A4,budget!$A$5:$I$337,7,FALSE) -> 0 | R4: =VLOOKUP(A4,budget!$A$5:$I$337,8,FALSE) -> 상시 무료 관람 (식음료 및 개인소모품비 제외) | S4: =VLOOKUP(A4,budget!$A$5:$I$337,9,FALSE) -> http://place.map.kakao.com/1310990190 | T4: =VLOOKUP(B4,api!$A$2:$R$334,17,FALSE) -> 128.8171 | U4: =VLOOKUP(B4,api!$A$2:$R$334,18,FALSE) -> 37.912407
A5: 23794385 | B5: DMZ박물관 | C5: =VLOOKUP(A5,budget!$A$5:$I$337,3,FALSE) -> DMZ박물관 | D5: =VLOOKUP(B5,api!$A$2:$R$334,2,FALSE) -> 고성군 | E5: =VLOOKUP(B5,api!$A$2:$R$334,12,FALSE) -> 강원특별자치도 고성군 현내면 송현리 212 | F5: 실내 | G5: =VLOOKUP(A5,budget!$A$5:$I$337,4,FALSE) -> 문화/전람/동굴/전망시설 | H5: CT1 | I5: 문화시설 | J5: =VLOOKUP(A5,budget!$A$5:$I$337,5,FALSE) -> 09:00 - 18:00 (입장마감 17:00, 월요일 휴무) | K5: =VLOOKUP(B5,api!$A$2:$R$334,14,FALSE) -> 033-681-0625 | L5: =VLOOKUP(B5,api!$A$2:$R$334,4,FALSE) -> https://www.dmzmuseum.com | M5: =VLOOKUP(B5,api!$A$2:$R$334,5,FALSE) -> 4.5 | N5: =VLOOKUP(B5,api!$A$2:$R$334,6,FALSE) -> 56 | O5: =VLOOKUP(B5,api!$A$2:$R$334,7,FALSE) -> 214 | P5: =VLOOKUP(A5,budget!$A$5:$I$337,6,FALSE) -> 2000 | Q5: =VLOOKUP(A5,budget!$A$5:$I$337,7,FALSE) -> 10000 | R5: =VLOOKUP(A5,budget!$A$5:$I$337,8,FALSE) -> 대인 관람료 및 전망대/스카이워크 이용료 기준 | S5: =VLOOKUP(A5,budget!$A$5:$I$337,9,FALSE) -> http://place.map.kakao.com/23794385 | T5: =VLOOKUP(B5,api!$A$2:$R$334,17,FALSE) -> 128.38257 | U5: =VLOOKUP(B5,api!$A$2:$R$334,18,FALSE) -> 38.576256
A6: 1389012423 | B6: DMZ생태평화공원 | C6: =VLOOKUP(A6,budget!$A$5:$I$337,3,FALSE) -> 철원DMZ생태평화공원 | D6: =VLOOKUP(B6,api!$A$2:$R$334,2,FALSE) -> 철원군 | E6: =VLOOKUP(B6,api!$A$2:$R$334,12,FALSE) -> 강원특별자치도 철원군 김화읍 생창리 85-7 | F6: 실외 | G6: =VLOOKUP(A6,budget!$A$5:$I$337,4,FALSE) -> 자연경관/자유관광지 | J6: =VLOOKUP(A6,budget!$A$5:$I$337,5,FALSE) -> 24시간 연중무휴 (자유 방문) | K6: =VLOOKUP(B6,api!$A$2:$R$334,14,FALSE) -> 033-458-3633 | L6: =VLOOKUP(B6,api!$A$2:$R$334,4,FALSE) -> 0 | M6: =VLOOKUP(B6,api!$A$2:$R$334,5,FALSE) -> 4.3 | N6: =VLOOKUP(B6,api!$A$2:$R$334,6,FALSE) -> 6 | O6: =VLOOKUP(B6,api!$A$2:$R$334,7,FALSE) -> 21 | P6: =VLOOKUP(A6,budget!$A$5:$I$337,6,FALSE) -> 0 | Q6: =VLOOKUP(A6,budget!$A$5:$I$337,7,FALSE) -> 0 | R6: =VLOOKUP(A6,budget!$A$5:$I$337,8,FALSE) -> 상시 무료 관람 (식음료 및 개인소모품비 제외) | S6: =VLOOKUP(A6,budget!$A$5:$I$337,9,FALSE) -> http://place.map.kakao.com/1389012423 | T6: =VLOOKUP(B6,api!$A$2:$R$334,17,FALSE) -> 127.45124 | U6: =VLOOKUP(B6,api!$A$2:$R$334,18,FALSE) -> 38.281017
A7: 8121115 | B7: 가령폭포 | C7: =VLOOKUP(A7,budget!$A$5:$I$337,3,FALSE) -> 가령폭포 | D7: =VLOOKUP(B7,api!$A$2:$R$334,2,FALSE) -> 홍천군 | E7: =VLOOKUP(B7,api!$A$2:$R$334,12,FALSE) -> 강원특별자치도 홍천군 내촌면 와야리 | F7: 실외 | G7: =VLOOKUP(A7,budget!$A$5:$I$337,4,FALSE) -> 자연경관/자유관광지 | J7: =VLOOKUP(A7,budget!$A$5:$I$337,5,FALSE) -> 24시간 연중무휴 (자유 방문) | K7: =VLOOKUP(B7,api!$A$2:$R$334,14,FALSE) -> 033-433-3003 | L7: =VLOOKUP(B7,api!$A$2:$R$334,4,FALSE) -> https://www.hongcheon.go.kr/ | M7: =VLOOKUP(B7,api!$A$2:$R$334,5,FALSE) -> 5 | N7: =VLOOKUP(B7,api!$A$2:$R$334,6,FALSE) -> 9 | O7: =VLOOKUP(B7,api!$A$2:$R$334,7,FALSE) -> 27 | P7: =VLOOKUP(A7,budget!$A$5:$I$337,6,FALSE) -> 0 | Q7: =VLOOKUP(A7,budget!$A$5:$I$337,7,FALSE) -> 0 | R7: =VLOOKUP(A7,budget!$A$5:$I$337,8,FALSE) -> 상시 무료 관람 (식음료 및 개인소모품비 제외) | S7: =VLOOKUP(A7,budget!$A$5:$I$337,9,FALSE) -> http://place.map.kakao.com/8121115 | T7: =VLOOKUP(B7,api!$A$2:$R$334,17,FALSE) -> 128.16057 | U7: =VLOOKUP(B7,api!$A$2:$R$334,18,FALSE) -> 37.831651
A8: 26916317 | B8: 가리산레포츠파크 | C8: =VLOOKUP(A8,budget!$A$5:$I$337,3,FALSE) -> 가리산레포츠파크 | D8: =VLOOKUP(B8,api!$A$2:$R$334,2,FALSE) -> 홍천군 | E8: =VLOOKUP(B8,api!$A$2:$R$334,12,FALSE) -> 강원특별자치도 홍천군 두촌면 천현리 776 | F8: 실외 | G8: =VLOOKUP(A8,budget!$A$5:$I$337,4,FALSE) -> 자연경관/자유관광지 | J8: =VLOOKUP(A8,budget!$A$5:$I$337,5,FALSE) -> 24시간 연중무휴 (자유 방문) | K8: =VLOOKUP(B8,api!$A$2:$R$334,14,FALSE) -> 070-8831-8138 | L8: =VLOOKUP(B8,api!$A$2:$R$334,4,FALSE) -> https://www.hongcheon.go.kr/tour/contents.do?key=1892 | M8: =VLOOKUP(B8,api!$A$2:$R$334,5,FALSE) -> 0 | N8: =VLOOKUP(B8,api!$A$2:$R$334,6,FALSE) -> 30 | O8: =VLOOKUP(B8,api!$A$2:$R$334,7,FALSE) -> 86 | P8: =VLOOKUP(A8,budget!$A$5:$I$337,6,FALSE) -> 0 | Q8: =VLOOKUP(A8,budget!$A$5:$I$337,7,FALSE) -> 0 | R8: =VLOOKUP(A8,budget!$A$5:$I$337,8,FALSE) -> 상시 무료 관람 (식음료 및 개인소모품비 제외) | S8: =VLOOKUP(A8,budget!$A$5:$I$337,9,FALSE) -> http://place.map.kakao.com/26916317 | T8: =VLOOKUP(B8,api!$A$2:$R$334,17,FALSE) -> 127.98115 | U8: =VLOOKUP(B8,api!$A$2:$R$334,18,FALSE) -> 37.865638
A9: 26979861 | B9: 강릉선교장 | C9: =VLOOKUP(A9,budget!$A$5:$I$337,3,FALSE) -> 강릉선교장 | D9: =VLOOKUP(B9,api!$A$2:$R$334,2,FALSE) -> 강릉시 | E9: =VLOOKUP(B9,api!$A$2:$R$334,12,FALSE) -> 강원특별자치도 강릉시 운정동 431 | F9: 실외 | G9: =VLOOKUP(A9,budget!$A$5:$I$337,4,FALSE) -> 자연경관/자유관광지 | J9: =VLOOKUP(A9,budget!$A$5:$I$337,5,FALSE) -> 상시 개방 | K9: =VLOOKUP(B9,api!$A$2:$R$334,14,FALSE) -> 033-646-3270 | L9: =VLOOKUP(B9,api!$A$2:$R$334,4,FALSE) -> https://knsgj.net/ | M9: =VLOOKUP(B9,api!$A$2:$R$334,5,FALSE) -> 3.4 | N9: =VLOOKUP(B9,api!$A$2:$R$334,6,FALSE) -> 102 | O9: =VLOOKUP(B9,api!$A$2:$R$334,7,FALSE) -> 361 | P9: =VLOOKUP(A9,budget!$A$5:$I$337,6,FALSE) -> 0 | Q9: =VLOOKUP(A9,budget!$A$5:$I$337,7,FALSE) -> 0 | R9: =VLOOKUP(A9,budget!$A$5:$I$337,8,FALSE) -> 상시 무료 관람 (식음료 및 개인소모품비 제외) | S9: =VLOOKUP(A9,budget!$A$5:$I$337,9,FALSE) -> http://place.map.kakao.com/26979861 | T9: =VLOOKUP(B9,api!$A$2:$R$334,17,FALSE) -> 128.88517 | U9: =VLOOKUP(B9,api!$A$2:$R$334,18,FALSE) -> 37.786643
A10: 25856200 | B10: 강릉솔향수목원 | C10: =VLOOKUP(A10,budget!$A$5:$I$337,3,FALSE) -> 강릉솔향수목원 | D10: =VLOOKUP(B10,api!$A$2:$R$334,2,FALSE) -> 강릉시 | E10: =VLOOKUP(B10,api!$A$2:$R$334,12,FALSE) -> 강원특별자치도 강릉시 구정면 구정리 산 147-1 | F10: 실외 | G10: =VLOOKUP(A10,budget!$A$5:$I$337,4,FALSE) -> 휴양림/수목원 | H10: AT4 | I10: 관광명소 | J10: =VLOOKUP(A10,budget!$A$5:$I$337,5,FALSE) -> 09:00 - 18:00 (하절기) / 09:00 - 17:00 (동절기) | K10: =VLOOKUP(B10,api!$A$2:$R$334,14,FALSE) -> 033-660-2322 | L10: =VLOOKUP(B10,api!$A$2:$R$334,4,FALSE) -> http://www.gn.go.kr/solhyang/index.do | M10: =VLOOKUP(B10,api!$A$2:$R$334,5,FALSE) -> 4.7 | N10: =VLOOKUP(B10,api!$A$2:$R$334,6,FALSE) -> 86 | O10: =VLOOKUP(B10,api!$A$2:$R$334,7,FALSE) -> 254 | P10: =VLOOKUP(A10,budget!$A$5:$I$337,6,FALSE) -> 1000 | Q10: =VLOOKUP(A10,budget!$A$5:$I$337,7,FALSE) -> 5000 | R10: =VLOOKUP(A10,budget!$A$5:$I$337,8,FALSE) -> 국공립/민간 휴양림 입장료 기준 (숙박/체험비 제외) | S10: =VLOOKUP(A10,budget!$A$5:$I$337,9,FALSE) -> http://place.map.kakao.com/25856200 | T10: =VLOOKUP(B10,api!$A$2:$R$334,17,FALSE) -> 128.86147 | U10: =VLOOKUP(B10,api!$A$2:$R$334,18,FALSE) -> 37.697803
A11: 7960891 | B11: 강릉송정해변 | C11: =VLOOKUP(A11,budget!$A$5:$I$337,3,FALSE) -> 송정해변 | D11: =VLOOKUP(B11,api!$A$2:$R$334,2,FALSE) -> 강릉시 | E11: =VLOOKUP(B11,api!$A$2:$R$334,12,FALSE) -> 강원특별자치도 강릉시 송정동 산 1-4 | F11: 실외 | G11: =VLOOKUP(A11,budget!$A$5:$I$337,4,FALSE) -> 자연경관/자유관광지 | H11: AT4 | I11: 관광명소 | J11: =VLOOKUP(A11,budget!$A$5:$I$337,5,FALSE) -> 24시간 연중무휴 (자유 방문) | K11: =VLOOKUP(B11,api!$A$2:$R$334,14,FALSE) -> 033-660-3887 | L11: =VLOOKUP(B11,api!$A$2:$R$334,4,FALSE) -> https://www.gn.go.kr/tour/prog/lod/Sights/S01/sub02_02_01/view.do?cid=437 | M11: =VLOOKUP(B11,api!$A$2:$R$334,5,FALSE) -> 4.5 | N11: =VLOOKUP(B11,api!$A$2:$R$334,6,FALSE) -> 99 | O11: =VLOOKUP(B11,api!$A$2:$R$334,7,FALSE) -> 5 | P11: =VLOOKUP(A11,budget!$A$5:$I$337,6,FALSE) -> 0 | Q11: =VLOOKUP(A11,budget!$A$5:$I$337,7,FALSE) -> 0 | R11: =VLOOKUP(A11,budget!$A$5:$I$337,8,FALSE) -> 상시 무료 관람 (식음료 및 개인소모품비 제외) | S11: =VLOOKUP(A11,budget!$A$5:$I$337,9,FALSE) -> http://place.map.kakao.com/7960891 | T11: =VLOOKUP(B11,api!$A$2:$R$334,17,FALSE) -> 128.9378 | U11: =VLOOKUP(B11,api!$A$2:$R$334,18,FALSE) -> 37.779829
A12: 937891746 | B12: 강릉안반데기관광농원 | C12: =VLOOKUP(A12,budget!$A$5:$I$337,3,FALSE) -> 강릉안반데기관광농원 | D12: =VLOOKUP(B12,api!$A$2:$R$334,2,FALSE) -> 강릉시 | E12: =VLOOKUP(B12,api!$A$2:$R$334,12,FALSE) -> 강원특별자치도 강릉시 왕산면 대기리 2214-207 | F12: 실외 | G12: =VLOOKUP(A12,budget!$A$5:$I$337,4,FALSE) -> 자연경관/자유관광지 | H12: AT4 | I12: 관광명소 | J12: =VLOOKUP(A12,budget!$A$5:$I$337,5,FALSE) -> 상시 개방 | K12: =VLOOKUP(B12,api!$A$2:$R$334,14,FALSE) -> 033-644-8552 | L12: =VLOOKUP(B12,api!$A$2:$R$334,4,FALSE) -> https://blog.naver.com/sanai4744 | M12: =VLOOKUP(B12,api!$A$2:$R$334,5,FALSE) -> 3.6 | N12: =VLOOKUP(B12,api!$A$2:$R$334,6,FALSE) -> 9 | O12: =VLOOKUP(B12,api!$A$2:$R$334,7,FALSE) -> 59 | P12: =VLOOKUP(A12,budget!$A$5:$I$337,6,FALSE) -> 0 | Q12: =VLOOKUP(A12,budget!$A$5:$I$337,7,FALSE) -> 0 | R12: =VLOOKUP(A12,budget!$A$5:$I$337,8,FALSE) -> 상시 무료 관람 (식음료 및 개인소모품비 제외) | S12: =VLOOKUP(A12,budget!$A$5:$I$337,9,FALSE) -> http://place.map.kakao.com/937891746 | T12: =VLOOKUP(B12,api!$A$2:$R$334,17,FALSE) -> 128.74003 | U12: =VLOOKUP(B12,api!$A$2:$R$334,18,FALSE) -> 37.608742
A13: 2058461010 | B13: 강릉월화거리 | C13: =VLOOKUP(A13,budget!$A$5:$I$337,3,FALSE) -> 강릉월화거리 | D13: =VLOOKUP(B13,api!$A$2:$R$334,2,FALSE) -> 강릉시 | E13: =VLOOKUP(B13,api!$A$2:$R$334,12,FALSE) -> 강원특별자치도 강릉시 임당동 106-1 | F13: 실외 | G13: =VLOOKUP(A13,budget!$A$5:$I$337,4,FALSE) -> 자연경관/자유관광지 | H13: AT4 | I13: 관광명소 | J13: =VLOOKUP(A13,budget!$A$5:$I$337,5,FALSE) -> 24시간 연중무휴 (자유 방문) | K13: =VLOOKUP(B13,api!$A$2:$R$334,14,FALSE) -> 0 | L13: =VLOOKUP(B13,api!$A$2:$R$334,4,FALSE) -> https://www.gn.go.kr/tour/prog/lod/Sights/S03/sub02_04_01/view.do?cid=256422 | M13: =VLOOKUP(B13,api!$A$2:$R$334,5,FALSE) -> 3.9 | N13: =VLOOKUP(B13,api!$A$2:$R$334,6,FALSE) -> 55 | O13: =VLOOKUP(B13,api!$A$2:$R$334,7,FALSE) -> 219 | P13: =VLOOKUP(A13,budget!$A$5:$I$337,6,FALSE) -> 0 | Q13: =VLOOKUP(A13,budget!$A$5:$I$337,7,FALSE) -> 0 | R13: =VLOOKUP(A13,budget!$A$5:$I$337,8,FALSE) -> 상시 무료 관람 (식음료 및 개인소모품비 제외) | S13: =VLOOKUP(A13,budget!$A$5:$I$337,9,FALSE) -> http://place.map.kakao.com/2058461010 | T13: =VLOOKUP(B13,api!$A$2:$R$334,17,FALSE) -> 128.8975 | U13: =VLOOKUP(B13,api!$A$2:$R$334,18,FALSE) -> 37.75591
A14: 18525909 | B14: 강릉중앙시장 | C14: =VLOOKUP(A14,budget!$A$5:$I$337,3,FALSE) -> 강릉중앙시장 | D14: =VLOOKUP(B14,api!$A$2:$R$334,2,FALSE) -> 강릉시 | E14: =VLOOKUP(B14,api!$A$2:$R$334,12,FALSE) -> 강원특별자치도 강릉시 성남동 50 | F14: 실외 | G14: =VLOOKUP(A14,budget!$A$5:$I$337,4,FALSE) -> 자연경관/자유관광지 | J14: =VLOOKUP(A14,budget!$A$5:$I$337,5,FALSE) -> 24시간 연중무휴 (자유 방문) | K14: =VLOOKUP(B14,api!$A$2:$R$334,14,FALSE) -> 033-648-2285 | L14: =VLOOKUP(B14,api!$A$2:$R$334,4,FALSE) -> https://www.gn.go.kr/tour/index.do | M14: =VLOOKUP(B14,api!$A$2:$R$334,5,FALSE) -> 3.9 | N14: =VLOOKUP(B14,api!$A$2:$R$334,6,FALSE) -> 577 | O14: =VLOOKUP(B14,api!$A$2:$R$334,7,FALSE) -> 206 | P14: =VLOOKUP(A14,budget!$A$5:$I$337,6,FALSE) -> 0 | Q14: =VLOOKUP(A14,budget!$A$5:$I$337,7,FALSE) -> 0 | R14: =VLOOKUP(A14,budget!$A$5:$I$337,8,FALSE) -> 상시 무료 관람 (식음료 및 개인소모품비 제외) | S14: =VLOOKUP(A14,budget!$A$5:$I$337,9,FALSE) -> http://place.map.kakao.com/18525909 | T14: =VLOOKUP(B14,api!$A$2:$R$334,17,FALSE) -> 128.89862 | U14: =VLOOKUP(B14,api!$A$2:$R$334,18,FALSE) -> 37.754025
A15: 14862993 | B15: 강릉카페거리 | C15: =VLOOKUP(A15,budget!$A$5:$I$337,3,FALSE) -> 강릉카페거리 | D15: =VLOOKUP(B15,api!$A$2:$R$334,2,FALSE) -> 강릉시 | E15: =VLOOKUP(B15,api!$A$2:$R$334,12,FALSE) -> 강원특별자치도 강릉시 견소동 287-90 | F15: 실외 | G15: =VLOOKUP(A15,budget!$A$5:$I$337,4,FALSE) -> 자연경관/자유관광지 | H15: AT4 | I15: 관광명소 | J15: =VLOOKUP(A15,budget!$A$5:$I$337,5,FALSE) -> 24시간 연중무휴 (자유 방문) | K15: =VLOOKUP(B15,api!$A$2:$R$334,14,FALSE) -> 0 | L15: =VLOOKUP(B15,api!$A$2:$R$334,4,FALSE) -> https://ggcoffeestreet.modoo.at/ | M15: =VLOOKUP(B15,api!$A$2:$R$334,5,FALSE) -> 4 | N15: =VLOOKUP(B15,api!$A$2:$R$334,6,FALSE) -> 94 | O15: =VLOOKUP(B15,api!$A$2:$R$334,7,FALSE) -> 183 | P15: =VLOOKUP(A15,budget!$A$5:$I$337,6,FALSE) -> 0 | Q15: =VLOOKUP(A15,budget!$A$5:$I$337,7,FALSE) -> 0 | R15: =VLOOKUP(A15,budget!$A$5:$I$337,8,FALSE) -> 상시 무료 관람 (식음료 및 개인소모품비 제외) | S15: =VLOOKUP(A15,budget!$A$5:$I$337,9,FALSE) -> http://place.map.kakao.com/14862993 | T15: =VLOOKUP(B15,api!$A$2:$R$334,17,FALSE) -> 128.94724 | U15: =VLOOKUP(B15,api!$A$2:$R$334,18,FALSE) -> 37.772654
A16: 714254383 | B16: 강릉해중공원 | C16: =VLOOKUP(A16,budget!$A$5:$I$337,3,FALSE) -> 강릉해중공원 | D16: =VLOOKUP(B16,api!$A$2:$R$334,2,FALSE) -> 강릉시 | E16: =VLOOKUP(B16,api!$A$2:$R$334,12,FALSE) -> 강원특별자치도 강릉시 안현동 227-6 | F16: 실외 | G16: =VLOOKUP(A16,budget!$A$5:$I$337,4,FALSE) -> 자연경관/자유관광지 | J16: =VLOOKUP(A16,budget!$A$5:$I$337,5,FALSE) -> 24시간 연중무휴 (자유 방문) | K16: =VLOOKUP(B16,api!$A$2:$R$334,14,FALSE) -> 0 | L16: =VLOOKUP(B16,api!$A$2:$R$334,4,FALSE) -> https://www.gn.go.kr/tour/index.do | M16: =VLOOKUP(B16,api!$A$2:$R$334,5,FALSE) -> 4 | N16: =VLOOKUP(B16,api!$A$2:$R$334,6,FALSE) -> 1 | O16: =VLOOKUP(B16,api!$A$2:$R$334,7,FALSE) -> 0 | P16: =VLOOKUP(A16,budget!$A$5:$I$337,6,FALSE) -> 0 | Q16: =VLOOKUP(A16,budget!$A$5:$I$337,7,FALSE) -> 0 | R16: =VLOOKUP(A16,budget!$A$5:$I$337,8,FALSE) -> 상시 무료 관람 (식음료 및 개인소모품비 제외) | S16: =VLOOKUP(A16,budget!$A$5:$I$337,9,FALSE) -> http://place.map.kakao.com/714254383 | T16: =VLOOKUP(B16,api!$A$2:$R$334,17,FALSE) -> 128.89738 | U16: =VLOOKUP(B16,api!$A$2:$R$334,18,FALSE) -> 37.813595
A17: 8171435 | B17: 강원감영 | C17: =VLOOKUP(A17,budget!$A$5:$I$337,3,FALSE) -> 원주 강원감영 | D17: =VLOOKUP(B17,api!$A$2:$R$334,2,FALSE) -> 원주시 | E17: =VLOOKUP(B17,api!$A$2:$R$334,12,FALSE) -> 강원특별자치도 원주시 일산동 54-3 | F17: 실외 | G17: =VLOOKUP(A17,budget!$A$5:$I$337,4,FALSE) -> 자연경관/자유관광지 | J17: =VLOOKUP(A17,budget!$A$5:$I$337,5,FALSE) -> 상시 개방 | K17: =VLOOKUP(B17,api!$A$2:$R$334,14,FALSE) -> 033-747-2416 | L17: =VLOOKUP(B17,api!$A$2:$R$334,4,FALSE) -> http://gangwongamyoung500.com/ | M17: =VLOOKUP(B17,api!$A$2:$R$334,5,FALSE) -> 4.4 | N17: =VLOOKUP(B17,api!$A$2:$R$334,6,FALSE) -> 62 | O17: =VLOOKUP(B17,api!$A$2:$R$334,7,FALSE) -> 318 | P17: =VLOOKUP(A17,budget!$A$5:$I$337,6,FALSE) -> 0 | Q17: =VLOOKUP(A17,budget!$A$5:$I$337,7,FALSE) -> 0 | R17: =VLOOKUP(A17,budget!$A$5:$I$337,8,FALSE) -> 상시 무료 관람 (식음료 및 개인소모품비 제외) | S17: =VLOOKUP(A17,budget!$A$5:$I$337,9,FALSE) -> http://place.map.kakao.com/8171435 | T17: =VLOOKUP(B17,api!$A$2:$R$334,17,FALSE) -> 127.95042 | U17: =VLOOKUP(B17,api!$A$2:$R$334,18,FALSE) -> 37.347973
A18: 11046971 | B18: 강원도립화목원 | C18: =VLOOKUP(A18,budget!$A$5:$I$337,3,FALSE) -> 강원특별자치도립화목원 | D18: =VLOOKUP(B18,api!$A$2:$R$334,2,FALSE) -> 춘천시 | E18: =VLOOKUP(B18,api!$A$2:$R$334,12,FALSE) -> 강원특별자치도 춘천시 사농동 644-1 | F18: 실외 | G18: =VLOOKUP(A18,budget!$A$5:$I$337,4,FALSE) -> 자연경관/자유관광지 | H18: AT4 | I18: 관광명소 | J18: =VLOOKUP(A18,budget!$A$5:$I$337,5,FALSE) -> 상시 개방 | K18: =VLOOKUP(B18,api!$A$2:$R$334,14,FALSE) -> 033-248-6685 | L18: =VLOOKUP(B18,api!$A$2:$R$334,4,FALSE) -> https://www.gwpa.kr/ | M18: =VLOOKUP(B18,api!$A$2:$R$334,5,FALSE) -> 4.3 | N18: =VLOOKUP(B18,api!$A$2:$R$334,6,FALSE) -> 65 | O18: =VLOOKUP(B18,api!$A$2:$R$334,7,FALSE) -> 302 | P18: =VLOOKUP(A18,budget!$A$5:$I$337,6,FALSE) -> 0 | Q18: =VLOOKUP(A18,budget!$A$5:$I$337,7,FALSE) -> 0 | R18: =VLOOKUP(A18,budget!$A$5:$I$337,8,FALSE) -> 상시 무료 관람 (식음료 및 개인소모품비 제외) | S18: =VLOOKUP(A18,budget!$A$5:$I$337,9,FALSE) -> http://place.map.kakao.com/11046971 | T18: =VLOOKUP(B18,api!$A$2:$R$334,17,FALSE) -> 127.72569 | U18: =VLOOKUP(B18,api!$A$2:$R$334,18,FALSE) -> 37.923032
A19: 9675634 | B19: 강원종합박물관 | C19: =VLOOKUP(A19,budget!$A$5:$I$337,3,FALSE) -> 강원종합박물관 | D19: =VLOOKUP(B19,api!$A$2:$R$334,2,FALSE) -> 삼척시 | E19: =VLOOKUP(B19,api!$A$2:$R$334,12,FALSE) -> 강원특별자치도 삼척시 신기면 신기리 375-4 | F19: 실내 | G19: =VLOOKUP(A19,budget!$A$5:$I$337,4,FALSE) -> 문화/전람/동굴/전망시설 | H19: CT1 | I19: 문화시설 | J19: =VLOOKUP(A19,budget!$A$5:$I$337,5,FALSE) -> 09:00 - 18:00 (입장마감 17:00, 월요일 휴무) | K19: =VLOOKUP(B19,api!$A$2:$R$334,14,FALSE) -> 033-541-1523 | L19: =VLOOKUP(B19,api!$A$2:$R$334,4,FALSE) -> http://www.museum.gangwon.kr/ | M19: =VLOOKUP(B19,api!$A$2:$R$334,5,FALSE) -> 2.7 | N19: =VLOOKUP(B19,api!$A$2:$R$334,6,FALSE) -> 91 | O19: =VLOOKUP(B19,api!$A$2:$R$334,7,FALSE) -> 215 | P19: =VLOOKUP(A19,budget!$A$5:$I$337,6,FALSE) -> 2000 | Q19: =VLOOKUP(A19,budget!$A$5:$I$337,7,FALSE) -> 10000 | R19: =VLOOKUP(A19,budget!$A$5:$I$337,8,FALSE) -> 대인 관람료 및 전망대/스카이워크 이용료 기준 | S19: =VLOOKUP(A19,budget!$A$5:$I$337,9,FALSE) -> http://place.map.kakao.com/9675634 | T19: =VLOOKUP(B19,api!$A$2:$R$334,17,FALSE) -> 129.0865 | U19: =VLOOKUP(B19,api!$A$2:$R$334,18,FALSE) -> 37.350927
A20: 26388997 | B20: 강촌레일파크 경강 레일바이크 | C20: =VLOOKUP(A20,budget!$A$5:$I$337,3,FALSE) -> 강촌레일파크 경강 레일바이크 | D20: =VLOOKUP(B20,api!$A$2:$R$334,2,FALSE) -> 춘천시 | E20: =VLOOKUP(B20,api!$A$2:$R$334,12,FALSE) -> 강원특별자치도 춘천시 남산면 서천리 226-5 | F20: 실외 | G20: =VLOOKUP(A20,budget!$A$5:$I$337,4,FALSE) -> 체험/액티비티 | H20: AT4 | I20: 관광명소 | J20: =VLOOKUP(A20,budget!$A$5:$I$337,5,FALSE) -> 09:00 - 17:30 (회차별 운행) | K20: =VLOOKUP(B20,api!$A$2:$R$334,14,FALSE) -> 033-245-1000 | L20: =VLOOKUP(B20,api!$A$2:$R$334,4,FALSE) -> 0 | M20: =VLOOKUP(B20,api!$A$2:$R$334,5,FALSE) -> 4 | N20: =VLOOKUP(B20,api!$A$2:$R$334,6,FALSE) -> 23 | O20: =VLOOKUP(B20,api!$A$2:$R$334,7,FALSE) -> 73 | P20: =VLOOKUP(A20,budget!$A$5:$I$337,6,FALSE) -> 10000 | Q20: =VLOOKUP(A20,budget!$A$5:$I$337,7,FALSE) -> 35000 | R20: =VLOOKUP(A20,budget!$A$5:$I$337,8,FALSE) -> 1인 승선/체험권 기준 (코스 및 이용 상품에 따라 변동) | S20: =VLOOKUP(A20,budget!$A$5:$I$337,9,FALSE) -> http://place.map.kakao.com/26388997 | T20: =VLOOKUP(B20,api!$A$2:$R$334,17,FALSE) -> 127.55096 | U20: =VLOOKUP(B20,api!$A$2:$R$334,18,FALSE) -> 37.842744
A21: 18711877 | B21: 강촌레일파크 김유정레일바이크 | C21: =VLOOKUP(A21,budget!$A$5:$I$337,3,FALSE) -> 강촌레일파크 김유정레일바이크 | D21: =VLOOKUP(B21,api!$A$2:$R$334,2,FALSE) -> 춘천시 | E21: =VLOOKUP(B21,api!$A$2:$R$334,12,FALSE) -> 강원특별자치도 춘천시 신동면 증리 323-2 | F21: 실외 | G21: =VLOOKUP(A21,budget!$A$5:$I$337,4,FALSE) -> 체험/액티비티 | H21: AT4 | I21: 관광명소 | J21: =VLOOKUP(A21,budget!$A$5:$I$337,5,FALSE) -> 09:00 - 17:30 (회차별 운행) | K21: =VLOOKUP(B21,api!$A$2:$R$334,14,FALSE) -> 033-245-1000 | L21: =VLOOKUP(B21,api!$A$2:$R$334,4,FALSE) -> https://www.railpark.co.kr/ | M21: =VLOOKUP(B21,api!$A$2:$R$334,5,FALSE) -> 3.8 | N21: =VLOOKUP(B21,api!$A$2:$R$334,6,FALSE) -> 145 | O21: =VLOOKUP(B21,api!$A$2:$R$334,7,FALSE) -> 265 | P21: =VLOOKUP(A21,budget!$A$5:$I$337,6,FALSE) -> 10000 | Q21: =VLOOKUP(A21,budget!$A$5:$I$337,7,FALSE) -> 35000 | R21: =VLOOKUP(A21,budget!$A$5:$I$337,8,FALSE) -> 1인 승선/체험권 기준 (코스 및 이용 상품에 따라 변동) | S21: =VLOOKUP(A21,budget!$A$5:$I$337,9,FALSE) -> http://place.map.kakao.com/18711877 | T21: =VLOOKUP(B21,api!$A$2:$R$334,17,FALSE) -> 127.71233 | U21: =VLOOKUP(B21,api!$A$2:$R$334,18,FALSE) -> 37.815773
A22: 8171586 | B22: 건봉사 | C22: =VLOOKUP(A22,budget!$A$5:$I$337,3,FALSE) -> 건봉사 | D22: =VLOOKUP(B22,api!$A$2:$R$334,2,FALSE) -> 고성군 | E22: =VLOOKUP(B22,api!$A$2:$R$334,12,FALSE) -> 강원특별자치도 고성군 거진읍 냉천리 36 | F22: 실외 | G22: =VLOOKUP(A22,budget!$A$5:$I$337,4,FALSE) -> 자연경관/자유관광지 | J22: =VLOOKUP(A22,budget!$A$5:$I$337,5,FALSE) -> 24시간 연중무휴 (자유 방문) | K22: =VLOOKUP(B22,api!$A$2:$R$334,14,FALSE) -> 033-682-8100 | L22: =VLOOKUP(B22,api!$A$2:$R$334,4,FALSE) -> https://www.gwgs.go.kr/tour/index.do | M22: =VLOOKUP(B22,api!$A$2:$R$334,5,FALSE) -> 4.6 | N22: =VLOOKUP(B22,api!$A$2:$R$334,6,FALSE) -> 44 | O22: =VLOOKUP(B22,api!$A$2:$R$334,7,FALSE) -> 182 | P22: =VLOOKUP(A22,budget!$A$5:$I$337,6,FALSE) -> 0 | Q22: =VLOOKUP(A22,budget!$A$5:$I$337,7,FALSE) -> 0 | R22: =VLOOKUP(A22,budget!$A$5:$I$337,8,FALSE) -> 상시 무료 관람 (식음료 및 개인소모품비 제외) | S22: =VLOOKUP(A22,budget!$A$5:$I$337,9,FALSE) -> http://place.map.kakao.com/8171586 | T22: =VLOOKUP(B22,api!$A$2:$R$334,17,FALSE) -> 128.37947 | U22: =VLOOKUP(B22,api!$A$2:$R$334,18,FALSE) -> 38.403158
A23: 910019105 | B23: 경포해변 중앙광장 | C23: =VLOOKUP(A23,budget!$A$5:$I$337,3,FALSE) -> 경포해변 중앙광장 | D23: =VLOOKUP(B23,api!$A$2:$R$334,2,FALSE) -> 강릉시 | E23: =VLOOKUP(B23,api!$A$2:$R$334,12,FALSE) -> 강원특별자치도 강릉시 강문동 산 1 | F23: 실외 | G23: =VLOOKUP(A23,budget!$A$5:$I$337,4,FALSE) -> 자연경관/자유관광지 | J23: =VLOOKUP(A23,budget!$A$5:$I$337,5,FALSE) -> 24시간 연중무휴 (자유 방문) | K23: =VLOOKUP(B23,api!$A$2:$R$334,14,FALSE) -> 0 | L23: =VLOOKUP(B23,api!$A$2:$R$334,4,FALSE) -> https://www.gn.go.kr/tour/prog/lod/Sights/S01/sub02_02_01/view.do?cid=434&orderBy=B&pageIndex=1&searchCondition=sj&searchKeyword=%EA%B2%BD%ED%8F%AC%ED%95%B4%EB%B3%80 | M23: =VLOOKUP(B23,api!$A$2:$R$334,5,FALSE) -> 4.7 | N23: =VLOOKUP(B23,api!$A$2:$R$334,6,FALSE) -> 3 | O23: =VLOOKUP(B23,api!$A$2:$R$334,7,FALSE) -> 4 | P23: =VLOOKUP(A23,budget!$A$5:$I$337,6,FALSE) -> 0 | Q23: =VLOOKUP(A23,budget!$A$5:$I$337,7,FALSE) -> 0 | R23: =VLOOKUP(A23,budget!$A$5:$I$337,8,FALSE) -> 상시 무료 관람 (식음료 및 개인소모품비 제외) | S23: =VLOOKUP(A23,budget!$A$5:$I$337,9,FALSE) -> http://place.map.kakao.com/910019105 | T23: =VLOOKUP(B23,api!$A$2:$R$334,17,FALSE) -> 128.9078 | U23: =VLOOKUP(B23,api!$A$2:$R$334,18,FALSE) -> 37.805138
A24: 8199114 | B24: 경포해수욕장 | C24: =VLOOKUP(A24,budget!$A$5:$I$337,3,FALSE) -> 경포해수욕장 | D24: =VLOOKUP(B24,api!$A$2:$R$334,2,FALSE) -> 강릉시 | E24: =VLOOKUP(B24,api!$A$2:$R$334,12,FALSE) -> 강원특별자치도 강릉시 강문동 산 1 | F24: 실외 | G24: =VLOOKUP(A24,budget!$A$5:$I$337,4,FALSE) -> 자연경관/자유관광지 | H24: AT4 | I24: 관광명소 | J24: =VLOOKUP(A24,budget!$A$5:$I$337,5,FALSE) -> 24시간 연중무휴 (자유 방문) | K24: =VLOOKUP(B24,api!$A$2:$R$334,14,FALSE) -> 0 | L24: =VLOOKUP(B24,api!$A$2:$R$334,4,FALSE) -> https://www.gn.go.kr/tour/prog/lod/Sights/S01/sub02_02_01/view.do?cid=434&orderBy=B&pageIndex=1&searchCondition=sj&searchKeyword=%EA%B2%BD%ED%8F%AC%ED%95%B4%EB%B3%80 | M24: =VLOOKUP(B24,api!$A$2:$R$334,5,FALSE) -> 4.4 | N24: =VLOOKUP(B24,api!$A$2:$R$334,6,FALSE) -> 217 | O24: =VLOOKUP(B24,api!$A$2:$R$334,7,FALSE) -> 38 | P24: =VLOOKUP(A24,budget!$A$5:$I$337,6,FALSE) -> 0 | Q24: =VLOOKUP(A24,budget!$A$5:$I$337,7,FALSE) -> 0 | R24: =VLOOKUP(A24,budget!$A$5:$I$337,8,FALSE) -> 상시 무료 관람 (식음료 및 개인소모품비 제외) | S24: =VLOOKUP(A24,budget!$A$5:$I$337,9,FALSE) -> http://place.map.kakao.com/8199114 | T24: =VLOOKUP(B24,api!$A$2:$R$334,17,FALSE) -> 128.91021 | U24: =VLOOKUP(B24,api!$A$2:$R$334,18,FALSE) -> 37.803406
A25: 12296544 | B25: 계방산 오토캠핑장 | C25: =VLOOKUP(A25,budget!$A$5:$I$337,3,FALSE) -> 계방산오토캠핑장 | D25: =VLOOKUP(B25,api!$A$2:$R$334,2,FALSE) -> 평창군 | E25: =VLOOKUP(B25,api!$A$2:$R$334,12,FALSE) -> 강원특별자치도 평창군 용평면 노동리 86 | F25: 실외 | G25: =VLOOKUP(A25,budget!$A$5:$I$337,4,FALSE) -> 캠핑/숙박시설 | H25: AD5 | I25: 숙박 | J25: =VLOOKUP(A25,budget!$A$5:$I$337,5,FALSE) -> 입실 14:00 / 퇴실 11:00 (상시) | K25: =VLOOKUP(B25,api!$A$2:$R$334,14,FALSE) -> 033-339-9016 | L25: =VLOOKUP(B25,api!$A$2:$R$334,4,FALSE) -> https://www.camfit.co.kr/camp/61d3a4fa5df366001e3f16a6 | M25: =VLOOKUP(B25,api!$A$2:$R$334,5,FALSE) -> 4.8 | N25: =VLOOKUP(B25,api!$A$2:$R$334,6,FALSE) -> 13 | O25: =VLOOKUP(B25,api!$A$2:$R$334,7,FALSE) -> 54 | P25: =VLOOKUP(A25,budget!$A$5:$I$337,6,FALSE) -> 0 | Q25: =VLOOKUP(A25,budget!$A$5:$I$337,7,FALSE) -> 0 | R25: =VLOOKUP(A25,budget!$A$5:$I$337,8,FALSE) -> 시설 이용 고객 대상 (단순 둘러보기/입장 무료) | S25: =VLOOKUP(A25,budget!$A$5:$I$337,9,FALSE) -> http://place.map.kakao.com/12296544 | T25: =VLOOKUP(B25,api!$A$2:$R$334,17,FALSE) -> 128.47937 | U25: =VLOOKUP(B25,api!$A$2:$R$334,18,FALSE) -> 37.700036
A26: 13266763 | B26: 고생대자연사박물관 | C26: =VLOOKUP(A26,budget!$A$5:$I$337,3,FALSE) -> 태백고생대자연사박물관 | D26: =VLOOKUP(B26,api!$A$2:$R$334,2,FALSE) -> 태백시 | E26: =VLOOKUP(B26,api!$A$2:$R$334,12,FALSE) -> 강원특별자치도 태백시 동점동 295 | F26: 실내 | G26: =VLOOKUP(A26,budget!$A$5:$I$337,4,FALSE) -> 문화/전람/동굴/전망시설 | H26: CT1 | I26: 문화시설 | J26: =VLOOKUP(A26,budget!$A$5:$I$337,5,FALSE) -> 09:00 - 18:00 (입장마감 17:00, 월요일 휴무) | K26: =VLOOKUP(B26,api!$A$2:$R$334,14,FALSE) -> 033-581-8181 | L26: =VLOOKUP(B26,api!$A$2:$R$334,4,FALSE) -> https://tour.taebaek.go.kr/tpmuseum | M26: =VLOOKUP(B26,api!$A$2:$R$334,5,FALSE) -> 4.5 | N26: =VLOOKUP(B26,api!$A$2:$R$334,6,FALSE) -> 30 | O26: =VLOOKUP(B26,api!$A$2:$R$334,7,FALSE) -> 141 | P26: =VLOOKUP(A26,budget!$A$5:$I$337,6,FALSE) -> 2000 | Q26: =VLOOKUP(A26,budget!$A$5:$I$337,7,FALSE) -> 10000 | R26: =VLOOKUP(A26,budget!$A$5:$I$337,8,FALSE) -> 대인 관람료 및 전망대/스카이워크 이용료 기준 | S26: =VLOOKUP(A26,budget!$A$5:$I$337,9,FALSE) -> http://place.map.kakao.com/13266763 | T26: =VLOOKUP(B26,api!$A$2:$R$334,17,FALSE) -> 129.03956 | U26: =VLOOKUP(B26,api!$A$2:$R$334,18,FALSE) -> 37.094919
A27: 8176583 | B27: 고석정 | C27: =VLOOKUP(A27,budget!$A$5:$I$337,3,FALSE) -> 고석정 | D27: =VLOOKUP(B27,api!$A$2:$R$334,2,FALSE) -> 철원군 | E27: =VLOOKUP(B27,api!$A$2:$R$334,12,FALSE) -> 강원특별자치도 철원군 동송읍 장흥리 725-13 | F27: 실외 | G27: =VLOOKUP(A27,budget!$A$5:$I$337,4,FALSE) -> 자연경관/자유관광지 | J27: =VLOOKUP(A27,budget!$A$5:$I$337,5,FALSE) -> 상시 개방 | K27: =VLOOKUP(B27,api!$A$2:$R$334,14,FALSE) -> 033-450-5558 | L27: =VLOOKUP(B27,api!$A$2:$R$334,4,FALSE) -> 0 | M27: =VLOOKUP(B27,api!$A$2:$R$334,5,FALSE) -> 4.4 | N27: =VLOOKUP(B27,api!$A$2:$R$334,6,FALSE) -> 179 | O27: =VLOOKUP(B27,api!$A$2:$R$334,7,FALSE) -> 88 | P27: =VLOOKUP(A27,budget!$A$5:$I$337,6,FALSE) -> 0 | Q27: =VLOOKUP(A27,budget!$A$5:$I$337,7,FALSE) -> 0 | R27: =VLOOKUP(A27,budget!$A$5:$I$337,8,FALSE) -> 상시 무료 관람 (식음료 및 개인소모품비 제외) | S27: =VLOOKUP(A27,budget!$A$5:$I$337,9,FALSE) -> http://place.map.kakao.com/8176583 | T27: =VLOOKUP(B27,api!$A$2:$R$334,17,FALSE) -> 127.28795 | U27: =VLOOKUP(B27,api!$A$2:$R$334,18,FALSE) -> 38.185262
A28: 984257114 | B28: 고성 서낭바위 | C28: =VLOOKUP(A28,budget!$A$5:$I$337,3,FALSE) -> 서낭바위 | D28: =VLOOKUP(B28,api!$A$2:$R$334,2,FALSE) -> 고성군 | E28: =VLOOKUP(B28,api!$A$2:$R$334,12,FALSE) -> 강원특별자치도 고성군 죽왕면 오호리 산 24-1 | F28: 실외 | G28: =VLOOKUP(A28,budget!$A$5:$I$337,4,FALSE) -> 자연경관/자유관광지 | J28: =VLOOKUP(A28,budget!$A$5:$I$337,5,FALSE) -> 상시 개방 | K28: =VLOOKUP(B28,api!$A$2:$R$334,14,FALSE) -> 0 | L28: =VLOOKUP(B28,api!$A$2:$R$334,4,FALSE) -> https://blog.naver.com/happy-goseong/222505032066 | M28: =VLOOKUP(B28,api!$A$2:$R$334,5,FALSE) -> 4.5 | N28: =VLOOKUP(B28,api!$A$2:$R$334,6,FALSE) -> 40 | O28: =VLOOKUP(B28,api!$A$2:$R$334,7,FALSE) -> 64 | P28: =VLOOKUP(A28,budget!$A$5:$I$337,6,FALSE) -> 0 | Q28: =VLOOKUP(A28,budget!$A$5:$I$337,7,FALSE) -> 0 | R28: =VLOOKUP(A28,budget!$A$5:$I$337,8,FALSE) -> 상시 무료 관람 (식음료 및 개인소모품비 제외) | S28: =VLOOKUP(A28,budget!$A$5:$I$337,9,FALSE) -> http://place.map.kakao.com/984257114 | T28: =VLOOKUP(B28,api!$A$2:$R$334,17,FALSE) -> 128.52993 | U28: =VLOOKUP(B28,api!$A$2:$R$334,18,FALSE) -> 38.327507
A29: 8127461 | B29: 고성 하늬라벤더팜 | C29: =VLOOKUP(A29,budget!$A$5:$I$337,3,FALSE) -> 하늬라벤더팜 | D29: =VLOOKUP(B29,api!$A$2:$R$334,2,FALSE) -> 고성군 | E29: =VLOOKUP(B29,api!$A$2:$R$334,12,FALSE) -> 강원특별자치도 고성군 간성읍 어천리 786-5 | F29: 실외 | G29: =VLOOKUP(A29,budget!$A$5:$I$337,4,FALSE) -> 자연경관/자유관광지 | J29: =VLOOKUP(A29,budget!$A$5:$I$337,5,FALSE) -> 상시 개방 | K29: =VLOOKUP(B29,api!$A$2:$R$334,14,FALSE) -> 033-681-0005 | L29: =VLOOKUP(B29,api!$A$2:$R$334,4,FALSE) -> https://www.lavenderfarm.co.kr/ | M29: =VLOOKUP(B29,api!$A$2:$R$334,5,FALSE) -> 3.3 | N29: =VLOOKUP(B29,api!$A$2:$R$334,6,FALSE) -> 76 | O29: =VLOOKUP(B29,api!$A$2:$R$334,7,FALSE) -> 527 | P29: =VLOOKUP(A29,budget!$A$5:$I$337,6,FALSE) -> 0 | Q29: =VLOOKUP(A29,budget!$A$5:$I$337,7,FALSE) -> 0 | R29: =VLOOKUP(A29,budget!$A$5:$I$337,8,FALSE) -> 상시 무료 관람 (식음료 및 개인소모품비 제외) | S29: =VLOOKUP(A29,budget!$A$5:$I$337,9,FALSE) -> http://place.map.kakao.com/8127461 | T29: =VLOOKUP(B29,api!$A$2:$R$334,17,FALSE) -> 128.41524 | U29: =VLOOKUP(B29,api!$A$2:$R$334,18,FALSE) -> 38.348549
A30: 1439312170 | B30: 고성통일전망타워 | C30: =VLOOKUP(A30,budget!$A$5:$I$337,3,FALSE) -> 고성통일전망타워 | D30: =VLOOKUP(B30,api!$A$2:$R$334,2,FALSE) -> 고성군 | E30: =VLOOKUP(B30,api!$A$2:$R$334,12,FALSE) -> 강원특별자치도 고성군 현내면 명호리 2-23 | F30: 실외 | G30: =VLOOKUP(A30,budget!$A$5:$I$337,4,FALSE) -> 문화/전람/동굴/전망시설 | H30: AT4 | I30: 관광명소 | J30: =VLOOKUP(A30,budget!$A$5:$I$337,5,FALSE) -> 10:00 - 18:00 (하절기/주말 연장운영) | K30: =VLOOKUP(B30,api!$A$2:$R$334,14,FALSE) -> 033-682-0088 | L30: =VLOOKUP(B30,api!$A$2:$R$334,4,FALSE) -> http://www.tongiltour.co.kr/ | M30: =VLOOKUP(B30,api!$A$2:$R$334,5,FALSE) -> 4.3 | N30: =VLOOKUP(B30,api!$A$2:$R$334,6,FALSE) -> 247 | O30: =VLOOKUP(B30,api!$A$2:$R$334,7,FALSE) -> 297 | P30: =VLOOKUP(A30,budget!$A$5:$I$337,6,FALSE) -> 2000 | Q30: =VLOOKUP(A30,budget!$A$5:$I$337,7,FALSE) -> 10000 | R30: =VLOOKUP(A30,budget!$A$5:$I$337,8,FALSE) -> 대인 관람료 및 전망대/스카이워크 이용료 기준 | S30: =VLOOKUP(A30,budget!$A$5:$I$337,9,FALSE) -> http://place.map.kakao.com/1439312170 | T30: =VLOOKUP(B30,api!$A$2:$R$334,17,FALSE) -> 128.37489 | U30: =VLOOKUP(B30,api!$A$2:$R$334,18,FALSE) -> 38.586687
A31: 11529179 | B31: 곰배령 | C31: =VLOOKUP(A31,budget!$A$5:$I$337,3,FALSE) -> 곰배령 | D31: =VLOOKUP(B31,api!$A$2:$R$334,2,FALSE) -> 인제군 | E31: =VLOOKUP(B31,api!$A$2:$R$334,12,FALSE) -> 강원특별자치도 인제군 기린면 진동리 | F31: 실외 | G31: =VLOOKUP(A31,budget!$A$5:$I$337,4,FALSE) -> 자연경관/자유관광지 | J31: =VLOOKUP(A31,budget!$A$5:$I$337,5,FALSE) -> 상시 개방 | K31: =VLOOKUP(B31,api!$A$2:$R$334,14,FALSE) -> 0 | L31: =VLOOKUP(B31,api!$A$2:$R$334,4,FALSE) -> 0 | M31: =VLOOKUP(B31,api!$A$2:$R$334,5,FALSE) -> 4.5 | N31: =VLOOKUP(B31,api!$A$2:$R$334,6,FALSE) -> 46 | O31: =VLOOKUP(B31,api!$A$2:$R$334,7,FALSE) -> 111 | P31: =VLOOKUP(A31,budget!$A$5:$I$337,6,FALSE) -> 0 | Q31: =VLOOKUP(A31,budget!$A$5:$I$337,7,FALSE) -> 0 | R31: =VLOOKUP(A31,budget!$A$5:$I$337,8,FALSE) -> 상시 무료 관람 (식음료 및 개인소모품비 제외) | S31: =VLOOKUP(A31,budget!$A$5:$I$337,9,FALSE) -> http://place.map.kakao.com/11529179 | T31: =VLOOKUP(B31,api!$A$2:$R$334,17,FALSE) -> 128.4334 | U31: =VLOOKUP(B31,api!$A$2:$R$334,18,FALSE) -> 38.027598
A32: 8235953 | B32: 구곡폭포 | C32: =VLOOKUP(A32,budget!$A$5:$I$337,3,FALSE) -> 구곡폭포 | D32: =VLOOKUP(B32,api!$A$2:$R$334,2,FALSE) -> 춘천시 | E32: =VLOOKUP(B32,api!$A$2:$R$334,12,FALSE) -> 강원특별자치도 춘천시 남산면 강촌리 432 | F32: 실외 | G32: =VLOOKUP(A32,budget!$A$5:$I$337,4,FALSE) -> 자연경관/자유관광지 | J32: =VLOOKUP(A32,budget!$A$5:$I$337,5,FALSE) -> 24시간 연중무휴 (자유 방문) | K32: =VLOOKUP(B32,api!$A$2:$R$334,14,FALSE) -> 033-261-0088 | L32: =VLOOKUP(B32,api!$A$2:$R$334,4,FALSE) -> http://tour.chuncheon.go.kr/ | M32: =VLOOKUP(B32,api!$A$2:$R$334,5,FALSE) -> 4.2 | N32: =VLOOKUP(B32,api!$A$2:$R$334,6,FALSE) -> 28 | O32: =VLOOKUP(B32,api!$A$2:$R$334,7,FALSE) -> 117 | P32: =VLOOKUP(A32,budget!$A$5:$I$337,6,FALSE) -> 0 | Q32: =VLOOKUP(A32,budget!$A$5:$I$337,7,FALSE) -> 0 | R32: =VLOOKUP(A32,budget!$A$5:$I$337,8,FALSE) -> 상시 무료 관람 (식음료 및 개인소모품비 제외) | S32: =VLOOKUP(A32,budget!$A$5:$I$337,9,FALSE) -> http://place.map.kakao.com/8235953 | T32: =VLOOKUP(B32,api!$A$2:$R$334,17,FALSE) -> 127.61585 | U32: =VLOOKUP(B32,api!$A$2:$R$334,18,FALSE) -> 37.797033
A33: 8214139 | B33: 구문소 | C33: =VLOOKUP(A33,budget!$A$5:$I$337,3,FALSE) -> 구문소 | D33: =VLOOKUP(B33,api!$A$2:$R$334,2,FALSE) -> 태백시 | E33: =VLOOKUP(B33,api!$A$2:$R$334,12,FALSE) -> 강원특별자치도 태백시 동점동 498-123 | F33: 실외 | G33: =VLOOKUP(A33,budget!$A$5:$I$337,4,FALSE) -> 자연경관/자유관광지 | J33: =VLOOKUP(A33,budget!$A$5:$I$337,5,FALSE) -> 상시 개방 | K33: =VLOOKUP(B33,api!$A$2:$R$334,14,FALSE) -> 0 | L33: =VLOOKUP(B33,api!$A$2:$R$334,4,FALSE) -> https://tour.taebaek.go.kr/ | M33: =VLOOKUP(B33,api!$A$2:$R$334,5,FALSE) -> 4.5 | N33: =VLOOKUP(B33,api!$A$2:$R$334,6,FALSE) -> 71 | O33: =VLOOKUP(B33,api!$A$2:$R$334,7,FALSE) -> 119 | P33: =VLOOKUP(A33,budget!$A$5:$I$337,6,FALSE) -> 0 | Q33: =VLOOKUP(A33,budget!$A$5:$I$337,7,FALSE) -> 0 | R33: =VLOOKUP(A33,budget!$A$5:$I$337,8,FALSE) -> 상시 무료 관람 (식음료 및 개인소모품비 제외) | S33: =VLOOKUP(A33,budget!$A$5:$I$337,9,FALSE) -> http://place.map.kakao.com/8214139 | T33: =VLOOKUP(B33,api!$A$2:$R$334,17,FALSE) -> 129.04233 | U33: =VLOOKUP(B33,api!$A$2:$R$334,18,FALSE) -> 37.092536
A34: 8713811 | B34: 국립가리왕산자연휴양림 | C34: =VLOOKUP(A34,budget!$A$5:$I$337,3,FALSE) -> 국립가리왕산자연휴양림 | D34: =VLOOKUP(B34,api!$A$2:$R$334,2,FALSE) -> 정선군 | E34: =VLOOKUP(B34,api!$A$2:$R$334,12,FALSE) -> 강원특별자치도 정선군 정선읍 회동리 308-1 | F34: 실외 | G34: =VLOOKUP(A34,budget!$A$5:$I$337,4,FALSE) -> 휴양림/수목원 | H34: AT4 | I34: 관광명소 | J34: =VLOOKUP(A34,budget!$A$5:$I$337,5,FALSE) -> 09:00 - 18:00 (화요일/월요일 휴무) | K34: =VLOOKUP(B34,api!$A$2:$R$334,14,FALSE) -> 033-562-5833 | L34: =VLOOKUP(B34,api!$A$2:$R$334,4,FALSE) -> https://www.foresttrip.go.kr/indvz/main.do?hmpgId=0113 | M34: =VLOOKUP(B34,api!$A$2:$R$334,5,FALSE) -> 0 | N34: =VLOOKUP(B34,api!$A$2:$R$334,6,FALSE) -> 0 | O34: =VLOOKUP(B34,api!$A$2:$R$334,7,FALSE) -> 0 | P34: =VLOOKUP(A34,budget!$A$5:$I$337,6,FALSE) -> 1000 | Q34: =VLOOKUP(A34,budget!$A$5:$I$337,7,FALSE) -> 5000 | R34: =VLOOKUP(A34,budget!$A$5:$I$337,8,FALSE) -> 국공립/민간 휴양림 입장료 기준 (숙박/체험비 제외) | S34: =VLOOKUP(A34,budget!$A$5:$I$337,9,FALSE) -> http://place.map.kakao.com/8713811 | T34: =VLOOKUP(B34,api!$A$2:$R$334,17,FALSE) -> 128.56964 | U34: =VLOOKUP(B34,api!$A$2:$R$334,18,FALSE) -> 37.426731
A35: 581564680 | B35: 국립강원전문과학관 | C35: =VLOOKUP(A35,budget!$A$5:$I$337,3,FALSE) -> 국립강원전문과학관 | D35: =VLOOKUP(B35,api!$A$2:$R$334,2,FALSE) -> 원주시 | E35: =VLOOKUP(B35,api!$A$2:$R$334,12,FALSE) -> 강원특별자치도 원주시 태장동 1191-6 | F35: 실내 | G35: =VLOOKUP(A35,budget!$A$5:$I$337,4,FALSE) -> 자연경관/자유관광지 | H35: CT1 | I35: 문화시설 | J35: =VLOOKUP(A35,budget!$A$5:$I$337,5,FALSE) -> 상시 개방 | K35: =VLOOKUP(B35,api!$A$2:$R$334,14,FALSE) -> 033-749-3500 | L35: =VLOOKUP(B35,api!$A$2:$R$334,4,FALSE) -> https://www.gwnsm.or.kr/ | M35: =VLOOKUP(B35,api!$A$2:$R$334,5,FALSE) -> 3.2 | N35: =VLOOKUP(B35,api!$A$2:$R$334,6,FALSE) -> 12 | O35: =VLOOKUP(B35,api!$A$2:$R$334,7,FALSE) -> 176 | P35: =VLOOKUP(A35,budget!$A$5:$I$337,6,FALSE) -> 0 | Q35: =VLOOKUP(A35,budget!$A$5:$I$337,7,FALSE) -> 0 | R35: =VLOOKUP(A35,budget!$A$5:$I$337,8,FALSE) -> 상시 무료 관람 (식음료 및 개인소모품비 제외) | S35: =VLOOKUP(A35,budget!$A$5:$I$337,9,FALSE) -> http://place.map.kakao.com/581564680 | T35: =VLOOKUP(B35,api!$A$2:$R$334,17,FALSE) -> 127.95339 | U35: =VLOOKUP(B35,api!$A$2:$R$334,18,FALSE) -> 37.391378
A36: 7879147 | B36: 국립미천골자연휴양림 | C36: =VLOOKUP(A36,budget!$A$5:$I$337,3,FALSE) -> 국립미천골자연휴양림 | D36: =VLOOKUP(B36,api!$A$2:$R$334,2,FALSE) -> 양양군 | E36: =VLOOKUP(B36,api!$A$2:$R$334,12,FALSE) -> 강원특별자치도 양양군 서면 미천리 산 5 | F36: 실외 | G36: =VLOOKUP(A36,budget!$A$5:$I$337,4,FALSE) -> 휴양림/수목원 | H36: AT4 | I36: 관광명소 | J36: =VLOOKUP(A36,budget!$A$5:$I$337,5,FALSE) -> 09:00 - 18:00 (화요일/월요일 휴무) | K36: =VLOOKUP(B36,api!$A$2:$R$334,14,FALSE) -> 033-673-1806 | L36: =VLOOKUP(B36,api!$A$2:$R$334,4,FALSE) -> https://www.foresttrip.go.kr/indvz/main.do?hmpgId=0112 | M36: =VLOOKUP(B36,api!$A$2:$R$334,5,FALSE) -> 4.7 | N36: =VLOOKUP(B36,api!$A$2:$R$334,6,FALSE) -> 32 | O36: =VLOOKUP(B36,api!$A$2:$R$334,7,FALSE) -> 2 | P36: =VLOOKUP(A36,budget!$A$5:$I$337,6,FALSE) -> 1000 | Q36: =VLOOKUP(A36,budget!$A$5:$I$337,7,FALSE) -> 5000 | R36: =VLOOKUP(A36,budget!$A$5:$I$337,8,FALSE) -> 국공립/민간 휴양림 입장료 기준 (숙박/체험비 제외) | S36: =VLOOKUP(A36,budget!$A$5:$I$337,9,FALSE) -> http://place.map.kakao.com/7879147 | T36: =VLOOKUP(B36,api!$A$2:$R$334,17,FALSE) -> 128.52806 | U36: =VLOOKUP(B36,api!$A$2:$R$334,18,FALSE) -> 37.939012
A37: 10389516 | B37: 국립백운산자연휴양림 | C37: =VLOOKUP(A37,budget!$A$5:$I$337,3,FALSE) -> 국립백운산자연휴양림 | D37: =VLOOKUP(B37,api!$A$2:$R$334,2,FALSE) -> 원주시 | E37: =VLOOKUP(B37,api!$A$2:$R$334,12,FALSE) -> 강원특별자치도 원주시 판부면 서곡리 1742-1 | F37: 실외 | G37: =VLOOKUP(A37,budget!$A$5:$I$337,4,FALSE) -> 휴양림/수목원 | H37: AT4 | I37: 관광명소 | J37: =VLOOKUP(A37,budget!$A$5:$I$337,5,FALSE) -> 09:00 - 18:00 (화요일/월요일 휴무) | K37: =VLOOKUP(B37,api!$A$2:$R$334,14,FALSE) -> 033-766-1063 | L37: =VLOOKUP(B37,api!$A$2:$R$334,4,FALSE) -> https://www.foresttrip.go.kr/indvz/main.do?hmpgId=0223 | M37: =VLOOKUP(B37,api!$A$2:$R$334,5,FALSE) -> 3.6 | N37: =VLOOKUP(B37,api!$A$2:$R$334,6,FALSE) -> 19 | O37: =VLOOKUP(B37,api!$A$2:$R$334,7,FALSE) -> 8 | P37: =VLOOKUP(A37,budget!$A$5:$I$337,6,FALSE) -> 1000 | Q37: =VLOOKUP(A37,budget!$A$5:$I$337,7,FALSE) -> 5000 | R37: =VLOOKUP(A37,budget!$A$5:$I$337,8,FALSE) -> 국공립/민간 휴양림 입장료 기준 (숙박/체험비 제외) | S37: =VLOOKUP(A37,budget!$A$5:$I$337,9,FALSE) -> http://place.map.kakao.com/10389516 | T37: =VLOOKUP(B37,api!$A$2:$R$334,17,FALSE) -> 127.94157 | U37: =VLOOKUP(B37,api!$A$2:$R$334,18,FALSE) -> 37.271561
A38: 8208782 | B38: 국립춘천박물관 | C38: =VLOOKUP(A38,budget!$A$5:$I$337,3,FALSE) -> 국립춘천박물관 | D38: =VLOOKUP(B38,api!$A$2:$R$334,2,FALSE) -> 춘천시 | E38: =VLOOKUP(B38,api!$A$2:$R$334,12,FALSE) -> 강원특별자치도 춘천시 석사동 95-3 | F38: 실내 | G38: =VLOOKUP(A38,budget!$A$5:$I$337,4,FALSE) -> 국공립 박물관/기념관 | H38: CT1 | I38: 문화시설 | J38: =VLOOKUP(A38,budget!$A$5:$I$337,5,FALSE) -> 09:00 - 18:00 (월요일 휴무) | K38: =VLOOKUP(B38,api!$A$2:$R$334,14,FALSE) -> 033-260-1500 | L38: =VLOOKUP(B38,api!$A$2:$R$334,4,FALSE) -> https://chuncheon.museum.go.kr/ | M38: =VLOOKUP(B38,api!$A$2:$R$334,5,FALSE) -> 4.6 | N38: =VLOOKUP(B38,api!$A$2:$R$334,6,FALSE) -> 63 | O38: =VLOOKUP(B38,api!$A$2:$R$334,7,FALSE) -> 841 | P38: =VLOOKUP(A38,budget!$A$5:$I$337,6,FALSE) -> 0 | Q38: =VLOOKUP(A38,budget!$A$5:$I$337,7,FALSE) -> 3000 | R38: =VLOOKUP(A38,budget!$A$5:$I$337,8,FALSE) -> 국공립 시설 무료 관람 또는 대인 기준 정가 | S38: =VLOOKUP(A38,budget!$A$5:$I$337,9,FALSE) -> http://place.map.kakao.com/8208782 | T38: =VLOOKUP(B38,api!$A$2:$R$334,17,FALSE) -> 127.75378 | U38: =VLOOKUP(B38,api!$A$2:$R$334,18,FALSE) -> 37.864059
A39: 1158129196 | B39: 국립춘천숲체원 | C39: =VLOOKUP(A39,budget!$A$5:$I$337,3,FALSE) -> 국립춘천숲체원 | D39: =VLOOKUP(B39,api!$A$2:$R$334,2,FALSE) -> 춘천시 | E39: =VLOOKUP(B39,api!$A$2:$R$334,12,FALSE) -> 강원특별자치도 춘천시 신북읍 발산리 산 32-1 | F39: 실외 | G39: =VLOOKUP(A39,budget!$A$5:$I$337,4,FALSE) -> 휴양림/수목원 | J39: =VLOOKUP(A39,budget!$A$5:$I$337,5,FALSE) -> 09:00 - 18:00 (화요일/월요일 휴무) | K39: =VLOOKUP(B39,api!$A$2:$R$334,14,FALSE) -> 033-260-5800 | L39: =VLOOKUP(B39,api!$A$2:$R$334,4,FALSE) -> https://ccfowi.modoo.at/ | M39: =VLOOKUP(B39,api!$A$2:$R$334,5,FALSE) -> 4.1 | N39: =VLOOKUP(B39,api!$A$2:$R$334,6,FALSE) -> 9 | O39: =VLOOKUP(B39,api!$A$2:$R$334,7,FALSE) -> 86 | P39: =VLOOKUP(A39,budget!$A$5:$I$337,6,FALSE) -> 1000 | Q39: =VLOOKUP(A39,budget!$A$5:$I$337,7,FALSE) -> 5000 | R39: =VLOOKUP(A39,budget!$A$5:$I$337,8,FALSE) -> 국공립/민간 휴양림 입장료 기준 (숙박/체험비 제외) | S39: =VLOOKUP(A39,budget!$A$5:$I$337,9,FALSE) -> http://place.map.kakao.com/1158129196 | T39: =VLOOKUP(B39,api!$A$2:$R$334,17,FALSE) -> 127.77181 | U39: =VLOOKUP(B39,api!$A$2:$R$334,18,FALSE) -> 37.980285
A40: 24505294 | B40: 국립횡성숲체원 | C40: =VLOOKUP(A40,budget!$A$5:$I$337,3,FALSE) -> 국립횡성숲체원 | D40: =VLOOKUP(B40,api!$A$2:$R$334,2,FALSE) -> 횡성군 | E40: =VLOOKUP(B40,api!$A$2:$R$334,12,FALSE) -> 강원특별자치도 횡성군 둔내면 삽교리 1767-10 | F40: 실외 | G40: =VLOOKUP(A40,budget!$A$5:$I$337,4,FALSE) -> 휴양림/수목원 | H40: AT4 | I40: 관광명소 | J40: =VLOOKUP(A40,budget!$A$5:$I$337,5,FALSE) -> 09:00 - 18:00 (화요일/월요일 휴무) | K40: =VLOOKUP(B40,api!$A$2:$R$334,14,FALSE) -> 033-340-6300 | L40: =VLOOKUP(B40,api!$A$2:$R$334,4,FALSE) -> https://hoengseong.fowi.or.kr/ | M40: =VLOOKUP(B40,api!$A$2:$R$334,5,FALSE) -> 4.5 | N40: =VLOOKUP(B40,api!$A$2:$R$334,6,FALSE) -> 45 | O40: =VLOOKUP(B40,api!$A$2:$R$334,7,FALSE) -> 188 | P40: =VLOOKUP(A40,budget!$A$5:$I$337,6,FALSE) -> 1000 | Q40: =VLOOKUP(A40,budget!$A$5:$I$337,7,FALSE) -> 5000 | R40: =VLOOKUP(A40,budget!$A$5:$I$337,8,FALSE) -> 국공립/민간 휴양림 입장료 기준 (숙박/체험비 제외) | S40: =VLOOKUP(A40,budget!$A$5:$I$337,9,FALSE) -> http://place.map.kakao.com/24505294 | T40: =VLOOKUP(B40,api!$A$2:$R$334,17,FALSE) -> 128.29146 | U40: =VLOOKUP(B40,api!$A$2:$R$334,18,FALSE) -> 37.536862
...

Sheet budget
B1: 강원 특별자치도 관광지별 예상 이용 금액 및 운영시간 (Min ~ Max 예산표)
B2: 총 관광지 수: 333개 | 기준: 1인당 순수 입장료/체험비 (주차비 제외) 및 대표 운영시간 정보
B4: 관광지명 | C4: 장소명 | D4: 카테고리 | E4: 운영시간 (휴무일 포함) | F4: 최소 금액 (Min/1인) | G4: 최대 금액 (Max/1인) | H4: 비고 (산출 근거) | I4: 상세URL
A5: 581024580 | B5: 2018 평창 동계올림픽대회 및 동계패럴림픽대회 기념관 | C5: 2018평창동계올림픽대회 및 동계패럴림픽대회기념관 | D5: 국공립 박물관/기념관 | E5: 09:00 - 18:00 (월요일 휴무) | F5: 0 | G5: 3000 | H5: 국공립 시설 무료 관람 또는 대인 기준 정가 | I5: http://place.map.kakao.com/581024580
A6: 25045748 | B6: 365세이프타운 | C6: 365세이프타운 | D6: 테마파크/민간관광지 | E6: 09:00 - 18:00 (월요일 휴무) | F6: 8000 | G6: 20000 | H6: 대인 정상 입장료 기준 (할인혜택/통합권 따라 변동) | I6: http://place.map.kakao.com/25045748
A7: 1310990190 | B7: BTS버스정류장 | C7: BTS 버스정류장 | D7: 자연경관/자유관광지 | E7: 상시 개방 | F7: 0 | G7: 0 | H7: 상시 무료 관람 (식음료 및 개인소모품비 제외) | I7: http://place.map.kakao.com/1310990190
A8: 23794385 | B8: DMZ박물관 | C8: DMZ박물관 | D8: 문화/전람/동굴/전망시설 | E8: 09:00 - 18:00 (입장마감 17:00, 월요일 휴무) | F8: 2000 | G8: 10000 | H8: 대인 관람료 및 전망대/스카이워크 이용료 기준 | I8: http://place.map.kakao.com/23794385
A9: 1389012423 | B9: DMZ생태평화공원 | C9: 철원DMZ생태평화공원 | D9: 자연경관/자유관광지 | E9: 24시간 연중무휴 (자유 방문) | F9: 0 | G9: 0 | H9: 상시 무료 관람 (식음료 및 개인소모품비 제외) | I9: http://place.map.kakao.com/1389012423
A10: 26847659 | B10: DMZ펀치볼둘레길 | C10: DMZ펀치볼둘레길 | D10: 자연경관/자유관광지 | E10: 24시간 연중무휴 (자유 방문) | F10: 0 | G10: 0 | H10: 상시 무료 관람 (식음료 및 개인소모품비 제외) | I10: http://place.map.kakao.com/26847659
A11: 8121115 | B11: 가령폭포 | C11: 가령폭포 | D11: 자연경관/자유관광지 | E11: 24시간 연중무휴 (자유 방문) | F11: 0 | G11: 0 | H11: 상시 무료 관람 (식음료 및 개인소모품비 제외) | I11: http://place.map.kakao.com/8121115
A12: 26916317 | B12: 가리산레포츠파크 | C12: 가리산레포츠파크 | D12: 자연경관/자유관광지 | E12: 24시간 연중무휴 (자유 방문) | F12: 0 | G12: 0 | H12: 상시 무료 관람 (식음료 및 개인소모품비 제외) | I12: http://place.map.kakao.com/26916317
A13: 8667927 | B13: 간현역 (폐역) | C13: 간현역 (폐역) | D13: 자연경관/자유관광지 | E13: 상시 개방 | F13: 0 | G13: 0 | H13: 상시 무료 관람 (식음료 및 개인소모품비 제외) | I13: http://place.map.kakao.com/8667927
A14: 8133638 | B14: 갈천약수터 | C14: 갈천약수터 | D14: 자연경관/자유관광지 | E14: 24시간 연중무휴 (자유 방문) | F14: 0 | G14: 0 | H14: 상시 무료 관람 (식음료 및 개인소모품비 제외) | I14: http://place.map.kakao.com/8133638
A15: 26979861 | B15: 강릉선교장 | C15: 강릉선교장 | D15: 자연경관/자유관광지 | E15: 상시 개방 | F15: 0 | G15: 0 | H15: 상시 무료 관람 (식음료 및 개인소모품비 제외) | I15: http://place.map.kakao.com/26979861
A16: 25856200 | B16: 강릉솔향수목원 | C16: 강릉솔향수목원 | D16: 휴양림/수목원 | E16: 09:00 - 18:00 (하절기) / 09:00 - 17:00 (동절기) | F16: 1000 | G16: 5000 | H16: 국공립/민간 휴양림 입장료 기준 (숙박/체험비 제외) | I16: http://place.map.kakao.com/25856200
... A140: 27002081 | B140: 선돌 | C140: 선돌 | D140: 자연경관/자유관광지 | E140: 상시 개방 | F140: 0 | G140: 0 | H140: 상시 무료 관람 (식음료 및 개인소모품비 제외) | I140: http://place.map.kakao.com/27002081
B141: 선바위 자연캠핑장 | D141: 캠핑/숙박시설 | E141: 입실 14:00 / 퇴실 11:00 (상시) | F141: 0 | G141: 0 | H141: 시설 이용 고객 대상 (단순 둘러보기/입장 무료)
A142: 21764909 | B142: 설악산 | C142: 설악산 | D142: 자연경관/자유관광지 | E142: 24시간 연중무휴 (자유 방문) | F142: 0 | G142: 0 | H142: 상시 무료 관람 (식음료 및 개인소모품비 제외) | I142: http://place.map.kakao.com/21764909
A143: 24414762 | B143: 설악산 자생식물원 | C143: 설악산자생식물원 | D143: 자연경관/자유관광지 | E143: 24시간 연중무휴 (자유 방문) | F143: 0 | G143: 0 | H143: 상시 무료 관람 (식음료 및 개인소모품비 제외) | I143: http://place.map.kakao.com/24414762
A144: 8376588 | B144: 설악해맞이공원 | C144: 설악해맞이공원 | D144: 자연경관/자유관광지 | E144: 24시간 연중무휴 (자유 방문) | F144: 0 | G144: 0 | H144: 상시 무료 관람 (식음료 및 개인소모품비 제외) | I144: http://place.map.kakao.com/8376588
A145: 118414704 | B145: 섬강 자작나무숲길 | C145: 섬강 자작나무숲길 | D145: 자연경관/자유관광지 | E145: 상시 개방 | F145: 0 | G145: 0 | H145: 상시 무료 관람 (식음료 및 개인소모품비 제외) | I145: http://place.map.kakao.com/118414704
A146: 1088147159 | B146: 소금강 전망대 | C146: 소금강 전망대 | D146: 자연경관/자유관광지 | E146: 24시간 연중무휴 (자유 방문) | F146: 0 | G146: 0 | H146: 상시 무료 관람 (식음료 및 개인소모품비 제외) | I146: http://place.map.kakao.com/1088147159
A147: 24662303 | B147: 소똥령 마을 | C147: 소똥령마을 농촌체험휴양마을 | D147: 자연경관/자유관광지 | E147: 상시 개방 | F147: 0 | G147: 0 | H147: 상시 무료 관람 (식음료 및 개인소모품비 제외) | I147: http://place.map.kakao.com/24662303
A148: 1323084049 | B148: 소양강 스카이워크 | C148: 소양강스카이워크 | D148: 문화/전람/동굴/전망시설 | E148: 10:00 - 18:00 (하절기/주말 연장운영) | F148: 2000 | G148: 10000 | H148: 대인 관람료 및 전망대/스카이워크 이용료 기준 | I148: http://place.map.kakao.com/1323084049
A149: 26919839 | B149: 소양강댐팔각정전망대 | C149: 소양강댐팔각정전망대 | D149: 자연경관/자유관광지 | E149: 24시간 연중무휴 (자유 방문) | F149: 0 | G149: 0 | H149: 상시 무료 관람 (식음료 및 개인소모품비 제외) | I149: http://place.map.kakao.com/26919839
A150: 1094955731 | B150: 소양강둘레길 (3코스) | C150: 소양강둘레길 (3코스) | D150: 자연경관/자유관광지 | E150: 24시간 연중무휴 (자유 방문) | F150: 0 | G150: 0 | H150: 상시 무료 관람 (식음료 및 개인소모품비 제외) | I150: http://place.map.kakao.com/1094955731
A151: 26558408 | B151: 소양강둘레길 내린길(2코스) | C151: 소양강둘레길 내린길(2코스) | D151: 자연경관/자유관광지 | E151: 24시간 연중무휴 (자유 방문) | F151: 0 | G151: 0 | H151: 상시 무료 관람 (식음료 및 개인소모품비 제외) | I151: http://place.map.kakao.com/26558408
A152: 26558407 | B152: 소양강둘레길 하늘길(1코스) | C152: 소양강둘레길 하늘길(1코스) | D152: 자연경관/자유관광지 | E152: 24시간 연중무휴 (자유 방문) | F152: 0 | G152: 0 | H152: 상시 무료 관람 (식음료 및 개인소모품비 제외) | I152: http://place.map.kakao.com/26558407
A153: 27460313 | B153: 소이산 | C153: 소이산 | D153: 자연경관/자유관광지 | E153: 24시간 연중무휴 (자유 방문) | F153: 0 | G153: 0 | H153: 상시 무료 관람 (식음료 및 개인소모품비 제외) | I153: http://place.map.kakao.com/27460313
... A267: 10838734 | B267: 추암촛대바위 | C267: 추암촛대바위 | D267: 자연경관/자유관광지 | E267: 05:00 - 18:00 (일몰 시까지) | F267: 0 | G267: 0 | H267: 상시 무료 관람 (식음료 및 개인소모품비 제외) | I267: http://place.map.kakao.com/10838734
B268: 춘천박사마을 어린이글램핑장 | D268: 캠핑/숙박시설 | E268: 입실 14:00 / 퇴실 11:00 (상시) | F268: 0 | G268: 0 | H268: 시설 이용 고객 대상 (단순 둘러보기/입장 무료)
A269: 1147568611 | B269: 춘천삼악산호수케이블카 | C269: 춘천삼악산호수케이블카 | D269: 체험/액티비티 | E269: 09:00 - 18:00 (매표마감 17:00) | F269: 10000 | G269: 35000 | H269: 1인 승선/체험권 기준 (코스 및 이용 상품에 따라 변동) | I269: http://place.map.kakao.com/1147568611
A270: 1691801060 | B270: 치악산국립공원 | C270: 치악산국립공원 | D270: 자연경관/자유관광지 | E270: 24시간 연중무휴 (자유 방문) | F270: 0 | G270: 0 | H270: 상시 무료 관람 (식음료 및 개인소모품비 제외) | I270: http://place.map.kakao.com/1691801060
A271: 8582434 | B271: 치악산자연휴양림 | C271: 치악산자연휴양림 | D271: 휴양림/수목원 | E271: 09:00 - 18:00 (화요일/월요일 휴무) | F271: 1000 | G271: 5000 | H271: 국공립/민간 휴양림 입장료 기준 (숙박/체험비 제외) | I271: http://place.map.kakao.com/8582434
A272: 666479885 | B272: 코이카 월드프렌즈빌리지 | C272: 코이카 월드프렌즈빌리지 | D272: 자연경관/자유관광지 | E272: 상시 개방 | F272: 0 | G272: 0 | H272: 상시 무료 관람 (식음료 및 개인소모품비 제외) | I272: http://place.map.kakao.com/666479885
A273: 1423911353 | B273: 킹카누나루터 | C273: 킹카누나루터 | D273: 체험/액티비티 | E273: 09:00 - 18:00 (사전예약/상황별 변동) | F273: 10000 | G273: 35000 | H273: 1인 승선/체험권 기준 (코스 및 이용 상품에 따라 변동) | I273: http://place.map.kakao.com/1423911353
A274: 14752201 | B274: 타임캡슐공원 | C274: 타임캡슐공원 | D274: 자연경관/자유관광지 | E274: 24시간 연중무휴 (자유 방문) | F274: 0 | G274: 0 | H274: 상시 무료 관람 (식음료 및 개인소모품비 제외) | I274: http://place.map.kakao.com/14752201
A275: 18896036 | B275: 탄광문화촌 | C275: 탄광문화촌 (휴관중) | D275: 자연경관/자유관광지 | E275: 상시 개방 | F275: 0 | G275: 0 | H275: 상시 무료 관람 (식음료 및 개인소모품비 제외) | I275: http://place.map.kakao.com/18896036
A276: 15166415 | B276: 태기산 | C276: 태기산 | D276: 자연경관/자유관광지 | E276: 24시간 연중무휴 (자유 방문) | F276: 0 | G276: 0 | H276: 상시 무료 관람 (식음료 및 개인소모품비 제외) | I276: http://place.map.kakao.com/15166415
A277: 8112646 | B277: 태기산 전망대 | C277: 태기산 전망대 | D277: 자연경관/자유관광지 | E277: 24시간 연중무휴 (자유 방문) | F277: 0 | G277: 0 | H277: 상시 무료 관람 (식음료 및 개인소모품비 제외) | I277: http://place.map.kakao.com/8112646
...

Sheet api
A1: 관광지명 | B1: 지역 | C1: 전화번호 | D1: 홈페이지 | E1: 평점 | F1: 평점건수 | G1: 리뷰수 | H1: 장소명 | I1: 세부카테고리 | J1: 카테고리코드 | K1: 카테고리명 | L1: 주소 | M1: 도로명주소 | N1: 전화번호 | O1: 장소ID | P1: 상세URL | Q1: 경도 | R1: 위도
A2: 2018 평창 동계올림픽대회 및 동계패럴림픽대회 기념관 | B2: 평창군 | C2: 033-330-5280 | D2: https://pom2018.org/ | E2: 4.7 | F2: 27 | G2: 173 | H2: 2018평창동계올림픽대회 및 동계패럴림픽대회기념관 | I2: 문화,예술 > 문화시설 > 기념관 | J2: CT1 | K2: 문화시설 | L2: 강원특별자치도 평창군 대관령면 횡계리 725 | M2: 강원특별자치도 평창군 대관령면 올림픽로 220 | N2: 033-330-5280 | O2: 581024580 | P2: http://place.map.kakao.com/581024580 | Q2: 128.70672 | R2: 37.666839
A3: 365세이프타운 | B3: 태백시 | C3: 0507-1495-7915 | D3: http://www.taebaek.go.kr/365safetown/index.do | E3: 4.5 | F3: 37 | G3: 163 | H3: 365세이프타운 | I3: 여행 > 관광,명소 > 테마파크 | J3: AT4 | K3: 관광명소 | L3: 강원특별자치도 태백시 장성동 31-2 | M3: 강원특별자치도 태백시 평화길 15 | N3: 033-550-3101 | O3: 25045748 | P3: http://place.map.kakao.com/25045748 | Q3: 129.02461 | R3: 37.100491
A4: BTS버스정류장 | B4: 강릉시 | C4: 033-640-5420 | D4: https://www.gn.go.kr/tour/index.do | E4: 4.3 | F4: 63 | G4: 113 | H4: BTS 버스정류장 | I4: 여행 > 관광,명소 > 촬영지 | L4: 강원특별자치도 강릉시 주문진읍 향호리 8-39 | O4: 1310990190 | P4: http://place.map.kakao.com/1310990190 | Q4: 128.8171 | R4: 37.912407
A5: DMZ박물관 | B5: 고성군 | C5: 033-634-8553 | D5: https://www.dmzmuseum.com | E5: 4.5 | F5: 56 | G5: 214 | H5: DMZ박물관 | I5: 문화,예술 > 문화시설 > 박물관 | J5: CT1 | K5: 문화시설 | L5: 강원특별자치도 고성군 현내면 송현리 212 | M5: 강원특별자치도 고성군 현내면 통일전망대로 369 | N5: 033-681-0625 | O5: 23794385 | P5: http://place.map.kakao.com/23794385 | Q5: 128.38257 | R5: 38.576256
A6: DMZ생태평화공원 | B6: 철원군 | C6: 033-458-3633 | E6: 4.3 | F6: 6 | G6: 21 | H6: 철원DMZ생태평화공원 | I6: 여행 > 공원 | L6: 강원특별자치도 철원군 김화읍 생창리 85-7 | M6: 강원특별자치도 철원군 김화읍 생창길 479 | N6: 033-458-3633 | O6: 1389012423 | P6: http://place.map.kakao.com/1389012423 | Q6: 127.45124 | R6: 38.281017
A7: DMZ펀치볼둘레길 | B7: 양구군 | C7: 033-481-8565 | D7: http://www.dmztrail.or.kr/ | E7: 3 | F7: 1 | G7: 9 | H7: DMZ펀치볼둘레길 | I7: 여행 > 관광,명소 > 도보여행 > 둘레길 | J7: AT4 | K7: 관광명소 | L7: 강원특별자치도 양구군 해안면 후리 621 | M7: 강원특별자치도 양구군 해안면 해안서화로 35 | N7: 033-481-8565 | O7: 26847659 | P7: http://place.map.kakao.com/26847659 | Q7: 128.14542 | R7: 38.290129
A8: 가령폭포 | B8: 홍천군 | C8: 033-430-2544 | D8: https://www.hongcheon.go.kr/ | E8: 5 | F8: 9 | G8: 27 | H8: 가령폭포 | I8: 여행 > 관광,명소 > 폭포 | L8: 강원특별자치도 홍천군 내촌면 와야리 | N8: 033-433-3003 | O8: 8121115 | P8: http://place.map.kakao.com/8121115 | Q8: 128.16057 | R8: 37.831651
A9: 가리산레포츠파크 | B9: 홍천군 | C9: 0507-1417-8138 | D9: https://www.hongcheon.go.kr/tour/contents.do?key=1892 | E9: 0 | F9: 30 | G9: 86 | H9: 가리산레포츠파크 | I9: 여행 > 체험여행 | L9: 강원특별자치도 홍천군 두촌면 천현리 776 | M9: 강원특별자치도 홍천군 두촌면 가리산길 426 | N9: 070-8831-8138 | O9: 26916317 | P9: http://place.map.kakao.com/26916317 | Q9: 127.98115 | R9: 37.865638
A10: 간현역 (폐역) | B10: 원주시 | C10: 033-733-6600 | D10: http://www.wjrailpark.com/ | E10: 4.4 | F10: 7 | G10: 3 | H10: 간현역 (폐역) | I10: 교통,수송 > 기차,철도 > 기차역 > 폐역 | L10: 강원특별자치도 원주시 지정면 간현리 870 | M10: 강원특별자치도 원주시 지정면 간현로 163 | N10: 1544-7788 | O10: 8667927 | P10: http://place.map.kakao.com/8667927 | Q10: 127.83702 | R10: 37.363406
A11: 갈천약수터 | B11: 양양군 | C11: 033-673-8799 | D11: https://tour.yangyang.go.kr/ | E11: 3.5 | F11: 2 | G11: 1 | H11: 갈천약수터 | I11: 여행 > 관광,명소 > 샘터,약수터 | L11: 강원특별자치도 양양군 서면 갈천리 104 | M11: 강원특별자치도 양양군 서면 구룡령로 1103-66 | N11: 033-673-8799 | O11: 8133638 | P11: http://place.map.kakao.com/8133638 | Q11: 128.50295 | R11: 37.905873
A12: 강릉선교장 | B12: 강릉시 | C12: 033-648-5303 | D12: https://knsgj.net/ | E12: 3.4 | F12: 102 | G12: 361 | H12: 강릉선교장 | I12: 여행 > 관광,명소 > 문화유적 | L12: 강원특별자치도 강릉시 운정동 431 | M12: 강원특별자치도 강릉시 운정길 63 | N12: 033-646-3270 | O12: 26979861 | P12: http://place.map.kakao.com/26979861 | Q12: 128.88517 | R12: 37.786643
A13: 강릉솔향수목원 | B13: 강릉시 | C13: 033-660-2322 | D13: http://www.gn.go.kr/solhyang/index.do | E13: 4.7 | F13: 86 | G13: 254 | H13: 강릉솔향수목원 | I13: 여행 > 관광,명소 > 수목원,식물원 | J13: AT4 | K13: 관광명소 | L13: 강원특별자치도 강릉시 구정면 구정리 산 147-1 | M13: 강원특별자치도 강릉시 구정면 수목원길 156 | N13: 033-660-2322 | O13: 25856200 | P13: http://place.map.kakao.com/25856200 | Q13: 128.86147 | R13: 37.697803
A14: 강릉송정해변 | B14: 강릉시 | C14: 033-660-3887 | D14: https://www.gn.go.kr/tour/prog/lod/Sights/S01/sub02_02_01/view.do?cid=437 | E14: 4.5 | F14: 99 | G14: 5 | H14: 송정해변 | I14: 여행 > 관광,명소 > 해수욕장,해변 | J14: AT4 | K14: 관광명소 | L14: 강원특별자치도 강릉시 송정동 산 1-4 | N14: 033-660-3887 | O14: 7960891 | P14: http://place.map.kakao.com/7960891 | Q14: 128.9378 | R14: 37.779829
A15: 강릉안반데기관광농원 | B15: 강릉시 | C15: 033-644-8552 | D15: https://blog.naver.com/sanai4744 | E15: 3.6 | F15: 9 | G15: 59 | H15: 강릉안반데기관광농원 | I15: 여행 > 관광,명소 > 관광농원 | J15: AT4 | K15: 관광명소 | L15: 강원특별자치도 강릉시 왕산면 대기리 2214-207 | M15: 강원특별자치도 강릉시 왕산면 안반데기1길 203 | N15: 033-644-8552 | O15: 937891746 | P15: http://place.map.kakao.com/937891746 | Q15: 128.74003 | R15: 37.608742
A16: 강릉월화거리 | B16: 강릉시 | C16: 033-640-4565 | D16: https://www.gn.go.kr/tour/prog/lod/Sights/S03/sub02_04_01/view.do?cid=256422 | E16: 3.9 | F16: 55 | G16: 219 | H16: 강릉월화거리 | I16: 여행 > 관광,명소 > 테마거리 | J16: AT4 | K16: 관광명소 | L16: 강원특별자치도 강릉시 임당동 106-1 | M16: 강원특별자치도 강릉시 경강로 2111 | O16: 2058461010 | P16: http://place.map.kakao.com/2058461010 | Q16: 128.8975 | R16: 37.75591
A17: 강릉중앙시장 | B17: 강릉시 | C17: 0507-1324-2285 | D17: https://www.gn.go.kr/tour/index.do | E17: 3.9 | F17: 577 | G17: 206 | H17: 강릉중앙시장 | I17: 가정,생활 > 시장 | L17: 강원특별자치도 강릉시 성남동 50 | M17: 강원특별자치도 강릉시 금성로 21 | N17: 033-648-2285 | O17: 18525909 | P17: http://place.map.kakao.com/18525909 | Q17: 128.89862 | R17: 37.754025
A18: 강릉카페거리 | B18: 강릉시 | C18: 033-640-5135 | D18: https://ggcoffeestreet.modoo.at/ | E18: 4 | F18: 94 | G18: 183 | H18: 강릉카페거리 | I18: 여행 > 관광,명소 > 테마거리 > 카페거리 | J18: AT4 | K18: 관광명소 | L18: 강원특별자치도 강릉시 견소동 287-90 | M18: 강원특별자치도 강릉시 창해로14번길 20 | O18: 14862993 | P18: http://place.map.kakao.com/14862993 | Q18: 128.94724 | R18: 37.772654
A19: 강릉해중공원 | B19: 강릉시 | C19: 033-640-5135 | D19: https://www.gn.go.kr/tour/index.do | E19: 4 | F19: 1 | G19: 0 | H19: 강릉해중공원 | I19: 여행 > 공원 | L19: 강원특별자치도 강릉시 안현동 227-6 | M19: 강원특별자치도 강릉시 해안로 634 | O19: 714254383 | P19: http://place.map.kakao.com/714254383 | Q19: 128.89738 | R19: 37.813595
A20: 강원감영 | B20: 원주시 | C20: 033-747-2416 | D20: http://gangwongamyoung500.com/ | E20: 4.4 | F20: 62 | G20: 318 | H20: 원주 강원감영 | I20: 여행 > 관광,명소 > 문화유적 > 유적지 | L20: 강원특별자치도 원주시 일산동 54-3 | M20: 강원특별자치도 원주시 원일로 77 | N20: 033-747-2416 | O20: 8171435 | P20: http://place.map.kakao.com/8171435 | Q20: 127.95042 | R20: 37.347973
A21: 강원도립화목원 | B21: 춘천시 | C21: 033-248-6685 | D21: https://www.gwpa.kr/ | E21: 4.3 | F21: 65 | G21: 302 | H21: 강원특별자치도립화목원 | I21: 여행 > 관광,명소 > 수목원,식물원 | J21: AT4 | K21: 관광명소 | L21: 강원특별자치도 춘천시 사농동 644-1 | M21: 강원특별자치도 춘천시 화목원길 24 | N21: 033-248-6685 | O21: 11046971 | P21: http://place.map.kakao.com/11046971 | Q21: 127.72569 | R21: 37.923032
A22: 강원도자연환경연구공원 | B22: 홍천군 | C22: 033-433-1994 | D22: https://ecopark.gwd.go.kr/portal | E22: 3 | F22: 4 | G22: 36 | H22: 강원특별자치도자연환경연구공원 | I22: 여행 > 공원 > 도시근린공원 | L22: 강원특별자치도 홍천군 북방면 성동리 1157-1 | M22: 강원특별자치도 홍천군 북방면 생태공원길 319 | N22: 033-248-6570 | O22: 13109251 | P22: http://place.map.kakao.com/13109251 | Q22: 127.85208 | R22: 37.754339
A23: 강원종합박물관 | B23: 삼척시 | C23: 033-541-1523 | D23: http://www.museum.gangwon.kr/ | E23: 2.7 | F23: 91 | G23: 215 | H23: 강원종합박물관 | I23: 문화,예술 > 문화시설 > 박물관 | J23: CT1 | K23: 문화시설 | L23: 강원특별자치도 삼척시 신기면 신기리 375-4 | M23: 강원특별자치도 삼척시 신기면 강원남부로 3016 | N23: 033-541-1523 | O23: 9675634 | P23: http://place.map.kakao.com/9675634 | Q23: 129.0865 | R23: 37.350927
A24: 강촌레일파크 경강 레일바이크 | B24: 춘천시 | C24: 033-245-1000 | E24: 4 | F24: 23 | G24: 73 | H24: 강촌레일파크 경강 레일바이크 | I24: 여행 > 관광,명소 > 테마파크 | J24: AT4 | K24: 관광명소 | L24: 강원특별자치도 춘천시 남산면 서천리 226-5 | M24: 강원특별자치도 춘천시 남산면 서백길 57 | N24: 033-245-1000 | O24: 26388997 | P24: http://place.map.kakao.com/26388997 | Q24: 127.55096 | R24: 37.842744
A25: 강촌레일파크 김유정레일바이크 | B25: 춘천시 | C25: 033-245-1000 | D25: https://www.railpark.co.kr/ | E25: 3.8 | F25: 145 | G25: 265 | H25: 강촌레일파크 김유정레일바이크 | I25: 여행 > 관광,명소 > 테마파크 | J25: AT4 | K25: 관광명소 | L25: 강원특별자치도 춘천시 신동면 증리 323-2 | M25: 강원특별자치도 춘천시 신동면 김유정로 1383 | N25: 033-245-1000 | O25: 18711877 | P25: http://place.map.kakao.com/18711877 | Q25: 127.71233 | R25: 37.815773
A26: 거례리사랑나무 | B26: 화천군 | C26: 033-442-1211 | E26: 3.9 | F26: 8 | G26: 26 | H26: 거례리사랑나무 | I26: 여행 > 관광,명소 | L26: 강원특별자치도 화천군 하남면 거례리 518-2 | O26: 23690312 | P26: http://place.map.kakao.com/23690312 | Q26: 127.68742 | R26: 38.072712
A27: 건봉사 | B27: 고성군 | C27: 033-682-8100 | D27: https://www.gwgs.go.kr/tour/index.do | E27: 4.6 | F27: 44 | G27: 182 | H27: 건봉사 | I27: 문화,예술 > 종교 > 불교 > 절,사찰 | L27: 강원특별자치도 고성군 거진읍 냉천리 36 | M27: 강원특별자치도 고성군 거진읍 건봉사로 723 | N27: 033-682-8100 | O27: 8171586 | P27: http://place.map.kakao.com/8171586 | Q27: 128.37947 | R27: 38.403158
A28: 경포해변 중앙광장 | B28: 강릉시 | C28: 0507-1320-4901 | D28: https://www.gn.go.kr/tour/prog/lod/Sights/S01/sub02_02_01/view.do?cid=434&orderBy=B&pageIndex=1&searchCondition=sj&searchKeyword=%EA%B2%BD%ED%8F%AC%ED%95%B4%EB%B3%80 | E28: 4.7 | F28: 3 | G28: 4 | H28: 경포해변 중앙광장 | I28: 여행 > 관광,명소 > 광장 | L28: 강원특별자치도 강릉시 강문동 산 1 | O28: 910019105 | P28: http://place.map.kakao.com/910019105 | Q28: 128.9078 | R28: 37.805138
A29: 경포해수욕장 | B29: 강릉시 | C29: 0507-1320-4901 | D29: https://www.gn.go.kr/tour/prog/lod/Sights/S01/sub02_02_01/view.do?cid=434&orderBy=B&pageIndex=1&searchCondition=sj&searchKeyword=%EA%B2%BD%ED%8F%AC%ED%95%B4%EB%B3%80 | E29: 4.4 | F29: 217 | G29: 38 | H29: 경포해수욕장 | I29: 여행 > 관광,명소 > 해수욕장,해변 | J29: AT4 | K29: 관광명소 | L29: 강원특별자치도 강릉시 강문동 산 1 | M29: 강원특별자치도 강릉시 창해로 514 | O29: 8199114 | P29: http://place.map.kakao.com/8199114 | Q29: 128.91021 | R29: 37.803406
A30: 계방산 오토캠핑장 | B30: 평창군 | C30: 033-339-9016 | D30: https://www.camfit.co.kr/camp/61d3a4fa5df366001e3f16a6 | E30: 4.8 | F30: 13 | G30: 54 | H30: 계방산오토캠핑장 | I30: 여행 > 숙박 > 야영,캠핑장 > 오토캠핑장 | J30: AD5 | K30: 숙박 | L30: 강원특별자치도 평창군 용평면 노동리 86 | M30: 강원특별자치도 평창군 용평면 이승복생가길 160 | N30: 033-339-9016 | O30: 12296544 | P30: http://place.map.kakao.com/12296544 | Q30: 128.47937 | R30: 37.700036
A31: 고생대자연사박물관 | B31: 태백시 | C31: 033-581-3003 | D31: https://tour.taebaek.go.kr/tpmuseum | E31: 4.5 | F31: 30 | G31: 141 | H31: 태백고생대자연사박물관 | I31: 문화,예술 > 문화시설 > 박물관 | J31: CT1 | K31: 문화시설 | L31: 강원특별자치도 태백시 동점동 295 | M31: 강원특별자치도 태백시 태백로 2249 | N31: 033-581-8181 | O31: 13266763 | P31: http://place.map.kakao.com/13266763 | Q31: 129.03956 | R31: 37.094919
A32: 고석정 | B32: 철원군 | C32: 033-450-5558 | E32: 4.4 | F32: 179 | G32: 88 | H32: 고석정 | I32: 여행 > 관광,명소 > 문화유적 | L32: 강원특별자치도 철원군 동송읍 장흥리 725-13 | N32: 033-450-5558 | O32: 8176583 | P32: http://place.map.kakao.com/8176583 | Q32: 127.28795 | R32: 38.185262
A33: 고성 서낭바위 | B33: 고성군 | C33: 033-680-3114 | D33: https://blog.naver.com/happy-goseong/222505032066 | E33: 4.5 | F33: 40 | G33: 64 | H33: 서낭바위 | I33: 여행 > 관광,명소 > 바위 | L33: 강원특별자치도 고성군 죽왕면 오호리 산 24-1 | O33: 984257114 | P33: http://place.map.kakao.com/984257114 | Q33: 128.52993 | R33: 38.327507
A34: 고성 하늬라벤더팜 | B34: 고성군 | C34: 033-681-0005 | D34: https://www.lavenderfarm.co.kr/ | E34: 3.3 | F34: 76 | G34: 527 | H34: 하늬라벤더팜 | I34: 서비스,산업 > 농업 > 원예업 | L34: 강원특별자치도 고성군 간성읍 어천리 786-5 | M34: 강원특별자치도 고성군 간성읍 꽃대마을길 175 | N34: 033-681-0005 | O34: 8127461 | P34: http://place.map.kakao.com/8127461 | Q34: 128.41524 | R34: 38.348549
